Workbook

Sheet 📖 How to Use
A1: 📖 How to Use This Tracker
A2: Bihar Home Construction — Project Home Tracker
B4: 🏗️ OVERVIEW
B5: This workbook tracks ALL expenses for your home construction in Bihar.
B6: It has 9 sheets. You mainly enter data in 2 sheets and the rest auto-calculate.
B8: 👉 YOU ENTER DATA IN:
B9: 1. "All Transactions" — Every material/service received
B10: 2. "Payment Tracker" — Every payment you make
B12: 👉 THESE AUTO-CALCULATE (don't edit formulas):
B13: 3. Material Summary — Total by material type
B14: 4. Monthly Summary — Spend by month
B15: 5. Vendor Summary — Billed vs Paid per vendor
B16: 6. Dashboard — KPI overview
B18: 👉 OPTIONAL SHEETS:
... B23: 📝 SHEET: "All Transactions" — YOUR MAIN ENTRY SHEET
B24: What to enter: | C24: One row for every material/item/service received.
B25: When to enter: | C25: Same day the material arrives or service is done.
B27: COLUMNS:
B28: Column A — Sr | C28: Auto-increment serial number (1, 2, 3...)
B29: Column B — Date | C29: Date of delivery/service (DD-MM-YYYY format)
B30: Column C — Month | C30: Text like "May-2026", "Jun-2026" (for SUMIFS)
B31: Column D — Phase | C31: Foundation / Plinth / Superstructure / Finishing
B32: Column E — Category | C32: Building Materials / Steel/Iron / Professional Fees / Land Development / Labour / Transport / etc.
B33: Column F — Subcategory | C33: Bricks / Cement-Ultratech Super / Tiscon-12mm / JCB / Earth Filling Labour / etc.
B34: Column G — Item Description | C34: Detailed description: "Tiscon 12mm TMT - 100 PC @ ₹908 (Bill 2)"
B35: Column H — Vendor | C35: Pappu Hardware / Brick Company / Econ Builder / etc.
B36: Column I — Qty | C36: Quantity (100, 50, 27.5, 17.5 etc.)
B37: Column J — Unit | C37: Pcs / Bags / Ton / CFT / Nos / Hrs / Lumpsum / L / Kg
B38: Column K — Rate | C38: Price per unit (₹908, ₹360, ₹8.5 etc.)
B39: Column L — Gross Amount | C39: Qty × Rate (enter manually: 100 × 908 = 90800)
... B44: Column Q — Payment Mode | C44: "GPay" / "Bank Transfer" / "Cash"
B46: 💡 TIP: Copy formulas from the row above when adding new rows (Col N and O).
B48: 💳 SHEET: "Payment Tracker" — CASH FLOW LOG
B49: What to enter: | C49: One row for every payment made (GPay, Bank, Cash).
B50: When to enter: | C50: Same day the payment is made.
B51: Why separate from Transactions? | C51: Because payments don't always match deliveries:
C52: • Advance payments (Brick Company ₹3.69L before delivery)
C53: • Part payments (Pappu Hardware Bill 63 paid in 2 parts)
C54: • One payment for multiple items (Bill 2 covers 8 items)
B56: COLUMNS:
...

Sheet Dashboard
A2: 🏠 BIHAR HOME BUILD — PROJECT DASHBOARD
A3: Plinth Phase · Started 7 May 2026 | G3: Auto-updates from All Transactions & Payment Tracker
B6: TOTAL CASH PAID | E6: MATERIAL ON SITE | H6: VENDOR ADVANCE | K6: BALANCE DUE
B7: =SUM('Payment Tracker'!G5:G100) -> 1334422 | E7: ='Vendor Summary'!C17 -> 1108712 | H7: =SUM('Payment Tracker'!G5:G100)-'Vendor Summary'!C17 -> 225710 | K7: ='Vendor Summary'!E17 -> -178900
B8: All payments made to date | E8: Billed value received | H8: Advance with Brick Co. | K8: Unpaid vendor bills
B10: 👥 WHO PAID | E10: 📊 CATEGORY BREAKDOWN | H10: 🏪 VENDOR STATUS
B11: Payer | C11: Amount ₹ | E11: Category | F11: Amount ₹ | H11: Vendor | I11: Billed ₹ | J11: Paid ₹ | K11: Pending ₹ | L11: Status
B12: Self-GPay | C12: =SUMIF('Payment Tracker'!C:C,B12,'Payment Tracker'!G:G) -> 658782 | E12: Building Materials | F12: =SUMIFS('All Transactions'!O:O,'All Transactions'!E:E,E12) -> 509782 | H12: Pappu Hardware | I12: =SUMIF('All Transactions'!H:H,H12,'All Transactions'!O:O) -> 414130 | J12: =SUMIF('Payment Tracker'!D:D,H12,'Payment Tracker'!G:G) -> 414130 | K12: =IF(I12=0,"—",I12-J12) -> 0 | L12: =IF(I12=0,"—",IF(K12>0,"⚠ DUE",IF(K12<0,"🔵 ADV","✅ PAID"))) -> ✅ PAID
B13: Self-Bank Transfer | C13: =SUMIF('Payment Tracker'!C:C,B13,'Payment Tracker'!G:G) -> 271480 | E13: Steel/Iron | F13: =SUMIFS('All Transactions'!O:O,'All Transactions'!E:E,E13) -> 342360 | H13: Brick Company | I13: =SUMIF('All Transactions'!H:H,H13,'All Transactions'!O:O) -> 153000 | J13: =SUMIF('Payment Tracker'!D:D,H13,'Payment Tracker'!G:G) -> 369000 | K13: =IF(I13=0,"—",I13-J13) -> -216000 | L13: =IF(I13=0,"—",IF(K13>0,"⚠ DUE",IF(K13<0,"🔵 ADV","✅ PAID"))) -> 🔵 ADV
B14: Papa | C14: =SUMIF('Payment Tracker'!C:C,B14,'Payment Tracker'!G:G) -> 235160 | E14: Professional Fees | F14: =SUMIFS('All Transactions'!O:O,'All Transactions'!E:E,E14) -> 226000 | H14: Econ Builder | I14: =SUMIF('All Transactions'!H:H,H14,'All Transactions'!O:O) -> 226000 | J14: =SUMIF('Payment Tracker'!D:D,H14,'Payment Tracker'!G:G) -> 226000 | K14: =IF(I14=0,"—",I14-J14) -> 0 | L14: =IF(I14=0,"—",IF(K14>0,"⚠ DUE",IF(K14<0,"🔵 ADV","✅ PAID"))) -> ✅ PAID
B15: Chota Bhai | C15: =SUMIF('Payment Tracker'!C:C,B15,'Payment Tracker'!G:G) -> 169000 | E15: Land Development | F15: =SUMIFS('All Transactions'!O:O,'All Transactions'!E:E,E15) -> 42100 | H15: Concrete Supplier | I15: =SUMIF('All Transactions'!H:H,H15,'All Transactions'!O:O) -> 161982 | J15: =SUMIF('Payment Tracker'!D:D,H15,'Payment Tracker'!G:G) -> 161982 | K15: =IF(I15=0,"—",I15-J15) -> 0 | L15: =IF(I15=0,"—",IF(K15>0,"⚠ DUE",IF(K15<0,"🔵 ADV","✅ PAID"))) -> ✅ PAID
B16: Through Sonbhai | C16: =SUMIF('Payment Tracker'!C:C,B16,'Payment Tracker'!G:G) -> 0 | E16: Labour | F16: =SUMIFS('All Transactions'!O:O,'All Transactions'!E:E,E16) -> 26220 | H16: Sand Truck Wala | I16: =SUMIF('All Transactions'!H:H,H16,'All Transactions'!O:O) -> 110000 | J16: =SUMIF('Payment Tracker'!D:D,H16,'Payment Tracker'!G:G) -> 110000 | K16: =IF(I16=0,"—",I16-J16) -> 0 | L16: =IF(I16=0,"—",IF(K16>0,"⚠ DUE",IF(K16<0,"🔵 ADV","✅ PAID"))) -> ✅ PAID
B17: TOTAL | C17: =SUM(C12:C16) -> 1334422 | E17: Transport | F17: =SUMIFS('All Transactions'!O:O,'All Transactions'!E:E,E17) -> 1300 | H17: Mukesh Yadav | I17: =SUMIF('All Transactions'!H:H,H17,'All Transactions'!O:O) -> 42100 | J17: =SUMIF('Payment Tracker'!D:D,H17,'Payment Tracker'!G:G) -> 5000 | K17: =IF(I17=0,"—",I17-J17) -> 37100 | L17: =IF(I17=0,"—",IF(K17>0,"⚠ DUE",IF(K17<0,"🔵 ADV","✅ PAID"))) -> ⚠ DUE
E18: Food/Provisions | F18: =SUMIFS('All Transactions'!O:O,'All Transactions'!E:E,E18) -> 3285 | H18: Naveen Hardware | I18: =SUMIF('All Transactions'!H:H,H18,'All Transactions'!O:O) -> 18650 | J18: =SUMIF('Payment Tracker'!D:D,H18,'Payment Tracker'!G:G) -> 18650 | K18: =IF(I18=0,"—",I18-J18) -> 0 | L18: =IF(I18=0,"—",IF(K18>0,"⚠ DUE",IF(K18<0,"🔵 ADV","✅ PAID"))) -> ✅ PAID
E19: Miscellaneous | F19: =SUMIFS('All Transactions'!O:O,'All Transactions'!E:E,E19) -> 4475 | H19: Daily Labour | I19: =SUMIF('All Transactions'!H:H,H19,'All Transactions'!O:O) -> 23100 | J19: =SUMIF('Payment Tracker'!D:D,H19,'Payment Tracker'!G:G) -> 23100 | K19: =IF(I19=0,"—",I19-J19) -> 0 | L19: =IF(I19=0,"—",IF(K19>0,"⚠ DUE",IF(K19<0,"🔵 ADV","✅ PAID"))) -> ✅ PAID
E20: TOTAL | F20: =SUM(F12:F19) -> 1155522 | H20: Local Purchase | I20: =SUMIF('All Transactions'!H:H,H20,'All Transactions'!O:O) -> 5060 | J20: =SUMIF('Payment Tracker'!D:D,H20,'Payment Tracker'!G:G) -> 5060 | K20: =IF(I20=0,"—",I20-J20) -> 0 | L20: =IF(I20=0,"—",IF(K20>0,"⚠ DUE",IF(K20<0,"🔵 ADV","✅ PAID"))) -> ✅ PAID
H21: Sonbhai-Coordinator | I21: =SUMIF('All Transactions'!H:H,H21,'All Transactions'!O:O) -> 1500 | J21: =SUMIF('Payment Tracker'!D:D,H21,'Payment Tracker'!G:G) -> 1500 | K21: =IF(I21=0,"—",I21-J21) -> 0 | L21: =IF(I21=0,"—",IF(K21>0,"⚠ DUE",IF(K21<0,"🔵 ADV","✅ PAID"))) -> ✅ PAID
H22: TOTAL | I22: =SUM(I12:I21) -> 1155522 | J22: =SUM(J12:J21) -> 1334422 | K22: =SUM(K12:K21) -> -178900
B24: 📦 MATERIALS ON SITE | K24: 📅 MONTHLY TREND
B25: Material | C25: Qty | D25: Unit | E25: Avg Rate | F25: Gross ₹ | G25: Disc ₹ | H25: Net ₹ | I25: % Share | K25: Month | L25: Spend ₹
B26: =IF('Material Summary'!B5<>"",'Material Summary'!B5,"") -> Bricks | C26: =IF('Material Summary'!C5<>"",'Material Summary'!C5,"") -> 18000 | D26: =IF('Material Summary'!D5<>"",'Material Summary'!D5,"") -> Nos/Trailor | E26: =IF('Material Summary'!E5<>"",'Material Summary'!E5,"") -> 8.5 | F26: =IF('Material Summary'!F5<>"",'Material Summary'!F5,"") -> 153000 | G26: =IF('Material Summary'!G5<>"",'Material Summary'!G5,"") -> 0 | H26: =IF('Material Summary'!H5<>"",'Material Summary'!H5,"") -> 153000 | I26: =IF('Material Summary'!I5<>"",'Material Summary'!I5,"") -> 0.17954754 | K26: May-2026 | L26: =SUMIFS('All Transactions'!O:O,'All Transactions'!C:C,K26) -> 829592
B27: =IF('Material Summary'!B6<>"",'Material Summary'!B6,"") -> Sand | C27: =IF('Material Summary'!C6<>"",'Material Summary'!C6,"") -> 1838 | D27: =IF('Material Summary'!D6<>"",'Material Summary'!D6,"") -> CFT | E27: =IF('Material Summary'!E6<>"",'Material Summary'!E6,"") -> 59.847661 | F27: =IF('Material Summary'!F6<>"",'Material Summary'!F6,"") -> 110000 | G27: =IF('Material Summary'!G6<>"",'Material Summary'!G6,"") -> 0 | H27: =IF('Material Summary'!H6<>"",'Material Summary'!H6,"") -> 110000 | I27: =IF('Material Summary'!I6<>"",'Material Summary'!I6,"") -> 0.12908647 | K27: Jun-2026 | L27: =SUMIFS('All Transactions'!O:O,'All Transactions'!C:C,K27) -> 325930
B28: =IF('Material Summary'!B7<>"",'Material Summary'!B7,"") -> Concrete/Gitti | C28: =IF('Material Summary'!C7<>"",'Material Summary'!C7,"") -> 65.14 | D28: =IF('Material Summary'!D7<>"",'Material Summary'!D7,"") -> Tonnes/Trailor | E28: =IF('Material Summary'!E7<>"",'Material Summary'!E7,"") -> 2486.6749 | F28: =IF('Material Summary'!F7<>"",'Material Summary'!F7,"") -> 161982 | G28: =IF('Material Summary'!G7<>"",'Material Summary'!G7,"") -> 0 | H28: =IF('Material Summary'!H7<>"",'Material Summary'!H7,"") -> 161982 | I28: =IF('Material Summary'!I7<>"",'Material Summary'!I7,"") -> 0.19008804 | K28: Jul-2026 | L28: =SUMIFS('All Transactions'!O:O,'All Transactions'!C:C,K28) -> 0
B29: =IF('Material Summary'!B8<>"",'Material Summary'!B8,"") -> Cement-Ultratech Super | C29: =IF('Material Summary'!C8<>"",'Material Summary'!C8,"") -> 200 | D29: =IF('Material Summary'!D8<>"",'Material Summary'!D8,"") -> Bags | E29: =IF('Material Summary'!E8<>"",'Material Summary'!E8,"") -> 360 | F29: =IF('Material Summary'!F8<>"",'Material Summary'!F8,"") -> 72000 | G29: =IF('Material Summary'!G8<>"",'Material Summary'!G8,"") -> 0 | H29: =IF('Material Summary'!H8<>"",'Material Summary'!H8,"") -> 72000 | I29: =IF('Material Summary'!I8<>"",'Material Summary'!I8,"") -> 0.08449296 | K29: Aug-2026 | L29: =SUMIFS('All Transactions'!O:O,'All Transactions'!C:C,K29) -> 0
B30: =IF('Material Summary'!B9<>"",'Material Summary'!B9,"") -> Cement-Ultratech Normal | C30: =IF('Material Summary'!C9<>"",'Material Summary'!C9,"") -> 0 | D30: =IF('Material Summary'!D9<>"",'Material Summary'!D9,"") -> Bags | E30: =IF('Material Summary'!E9<>"",'Material Summary'!E9,"") | F30: =IF('Material Summary'!F9<>"",'Material Summary'!F9,"") -> 0 | G30: =IF('Material Summary'!G9<>"",'Material Summary'!G9,"") -> 0 | H30: =IF('Material Summary'!H9<>"",'Material Summary'!H9,"") -> 0 | I30: =IF('Material Summary'!I9<>"",'Material Summary'!I9,"") -> 0 | K30: Sep-2026 | L30: =SUMIFS('All Transactions'!O:O,'All Transactions'!C:C,K30) -> 0
B31: =IF('Material Summary'!B10<>"",'Material Summary'!B10,"") -> Cement-Ultratech Prem | C31: =IF('Material Summary'!C10<>"",'Material Summary'!C10,"") -> 0 | D31: =IF('Material Summary'!D10<>"",'Material Summary'!D10,"") -> Bags | E31: =IF('Material Summary'!E10<>"",'Material Summary'!E10,"") | F31: =IF('Material Summary'!F10<>"",'Material Summary'!F10,"") -> 0 | G31: =IF('Material Summary'!G10<>"",'Material Summary'!G10,"") -> 0 | H31: =IF('Material Summary'!H10<>"",'Material Summary'!H10,"") -> 0 | I31: =IF('Material Summary'!I10<>"",'Material Summary'!I10,"") -> 0 | K31: Oct-2026 | L31: =SUMIFS('All Transactions'!O:O,'All Transactions'!C:C,K31) -> 0
B32: =IF('Material Summary'!B11<>"",'Material Summary'!B11,"") -> Dr Fixit | C32: =IF('Material Summary'!C11<>"",'Material Summary'!C11,"") -> 22 | D32: =IF('Material Summary'!D11<>"",'Material Summary'!D11,"") -> Litres | E32: =IF('Material Summary'!E11<>"",'Material Summary'!E11,"") -> 245.45455 | F32: =IF('Material Summary'!F11<>"",'Material Summary'!F11,"") -> 5400 | G32: =IF('Material Summary'!G11<>"",'Material Summary'!G11,"") -> 0 | H32: =IF('Material Summary'!H11<>"",'Material Summary'!H11,"") -> 5400 | I32: =IF('Material Summary'!I11<>"",'Material Summary'!I11,"") -> 0.006336972 | K32: Nov-2026 | L32: =SUMIFS('All Transactions'!O:O,'All Transactions'!C:C,K32) -> 0
B33: =IF('Material Summary'!B12<>"",'Material Summary'!B12,"") -> Pipe PVC/GI | C33: =IF('Material Summary'!C12<>"",'Material Summary'!C12,"") -> 0 | D33: =IF('Material Summary'!D12<>"",'Material Summary'!D12,"") -> Pcs | E33: =IF('Material Summary'!E12<>"",'Material Summary'!E12,"") | F33: =IF('Material Summary'!F12<>"",'Material Summary'!F12,"") -> 0 | G33: =IF('Material Summary'!G12<>"",'Material Summary'!G12,"") -> 0 | H33: =IF('Material Summary'!H12<>"",'Material Summary'!H12,"") -> 0 | I33: =IF('Material Summary'!I12<>"",'Material Summary'!I12,"") -> 0 | K33: Dec-2026 | L33: =SUMIFS('All Transactions'!O:O,'All Transactions'!C:C,K33) -> 0
B34: =IF('Material Summary'!B13<>"",'Material Summary'!B13,"") -> Cover Block | C34: =IF('Material Summary'!C13<>"",'Material Summary'!C13,"") -> 6 | D34: =IF('Material Summary'!D13<>"",'Material Summary'!D13,"") -> Packets | E34: =IF('Material Summary'!E13<>"",'Material Summary'!E13,"") -> 350 | F34: =IF('Material Summary'!F13<>"",'Material Summary'!F13,"") -> 2100 | G34: =IF('Material Summary'!G13<>"",'Material Summary'!G13,"") -> 0 | H34: =IF('Material Summary'!H13<>"",'Material Summary'!H13,"") -> 2100 | I34: =IF('Material Summary'!I13<>"",'Material Summary'!I13,"") -> 0.002464378 | K34: Jan-2027 | L34: =SUMIFS('All Transactions'!O:O,'All Transactions'!C:C,K34) -> 0
B35: =IF('Material Summary'!B14<>"",'Material Summary'!B14,"") -> Kala Panni/Tar | C35: =IF('Material Summary'!C14<>"",'Material Summary'!C14,"") -> 0 | D35: =IF('Material Summary'!D14<>"",'Material Summary'!D14,"") -> Kg | E35: =IF('Material Summary'!E14<>"",'Material Summary'!E14,"") | F35: =IF('Material Summary'!F14<>"",'Material Summary'!F14,"") -> 0 | G35: =IF('Material Summary'!G14<>"",'Material Summary'!G14,"") -> 0 | H35: =IF('Material Summary'!H14<>"",'Material Summary'!H14,"") -> 0 | I35: =IF('Material Summary'!I14<>"",'Material Summary'!I14,"") -> 0 | K35: Feb-2027 | L35: =SUMIFS('All Transactions'!O:O,'All Transactions'!C:C,K35) -> 0
B36: =IF('Material Summary'!B15<>"",'Material Summary'!B15,"") -> Bamboo/Shuttering | C36: =IF('Material Summary'!C15<>"",'Material Summary'!C15,"") -> 0 | D36: =IF('Material Summary'!D15<>"",'Material Summary'!D15,"") -> Nos | E36: =IF('Material Summary'!E15<>"",'Material Summary'!E15,"") | F36: =IF('Material Summary'!F15<>"",'Material Summary'!F15,"") -> 0 | G36: =IF('Material Summary'!G15<>"",'Material Summary'!G15,"") -> 0 | H36: =IF('Material Summary'!H15<>"",'Material Summary'!H15,"") -> 0 | I36: =IF('Material Summary'!I15<>"",'Material Summary'!I15,"") -> 0 | K36: Mar-2027 | L36: =SUMIFS('All Transactions'!O:O,'All Transactions'!C:C,K36) -> 0
B37: =IF('Material Summary'!B16<>"",'Material Summary'!B16,"") -> Nails | C37: =IF('Material Summary'!C16<>"",'Material Summary'!C16,"") -> 2 | D37: =IF('Material Summary'!D16<>"",'Material Summary'!D16,"") -> Kg/Bags | E37: =IF('Material Summary'!E16<>"",'Material Summary'!E16,"") -> 800 | F37: =IF('Material Summary'!F16<>"",'Material Summary'!F16,"") -> 1600 | G37: =IF('Material Summary'!G16<>"",'Material Summary'!G16,"") -> 0 | H37: =IF('Material Summary'!H16<>"",'Material Summary'!H16,"") -> 1600 | I37: =IF('Material Summary'!I16<>"",'Material Summary'!I16,"") -> 0.0018776213 | K37: Apr-2027 | L37: =SUMIFS('All Transactions'!O:O,'All Transactions'!C:C,K37) -> 0
B38: =IF('Material Summary'!B17<>"",'Material Summary'!B17,"") -> Binding Wire | C38: =IF('Material Summary'!C17<>"",'Material Summary'!C17,"") -> 21 | D38: =IF('Material Summary'!D17<>"",'Material Summary'!D17,"") -> Kg | E38: =IF('Material Summary'!E17<>"",'Material Summary'!E17,"") -> 176.19048 | F38: =IF('Material Summary'!F17<>"",'Material Summary'!F17,"") -> 3700 | G38: =IF('Material Summary'!G17<>"",'Material Summary'!G17,"") -> 0 | H38: =IF('Material Summary'!H17<>"",'Material Summary'!H17,"") -> 3700 | I38: =IF('Material Summary'!I17<>"",'Material Summary'!I17,"") -> 0.0043419993
B39: =IF('Material Summary'!B18<>"",'Material Summary'!B18,"") -> Blade | C39: =IF('Material Summary'!C18<>"",'Material Summary'!C18,"") -> 0 | D39: =IF('Material Summary'!D18<>"",'Material Summary'!D18,"") -> Pcs | E39: =IF('Material Summary'!E18<>"",'Material Summary'!E18,"") | F39: =IF('Material Summary'!F18<>"",'Material Summary'!F18,"") -> 0 | G39: =IF('Material Summary'!G18<>"",'Material Summary'!G18,"") -> 0 | H39: =IF('Material Summary'!H18<>"",'Material Summary'!H18,"") -> 0 | I39: =IF('Material Summary'!I18<>"",'Material Summary'!I18,"") -> 0
B40: =IF('Material Summary'!B19<>"",'Material Summary'!B19,"") -> Tiscon 16mm | C40: =IF('Material Summary'!C19<>"",'Material Summary'!C19,"") -> 0 | D40: =IF('Material Summary'!D19<>"",'Material Summary'!D19,"") -> Pcs | E40: =IF('Material Summary'!E19<>"",'Material Summary'!E19,"") | F40: =IF('Material Summary'!F19<>"",'Material Summary'!F19,"") -> 0 | G40: =IF('Material Summary'!G19<>"",'Material Summary'!G19,"") -> 0 | H40: =IF('Material Summary'!H19<>"",'Material Summary'!H19,"") -> 0 | I40: =IF('Material Summary'!I19<>"",'Material Summary'!I19,"") -> 0
B41: =IF('Material Summary'!B20<>"",'Material Summary'!B20,"") -> Tiscon 12mm | C41: =IF('Material Summary'!C20<>"",'Material Summary'!C20,"") -> 200 | D41: =IF('Material Summary'!D20<>"",'Material Summary'!D20,"") -> Pcs | E41: =IF('Material Summary'!E20<>"",'Material Summary'!E20,"") -> 908 | F41: =IF('Material Summary'!F20<>"",'Material Summary'!F20,"") -> 181600 | G41: =IF('Material Summary'!G20<>"",'Material Summary'!G20,"") -> 7264 | H41: =IF('Material Summary'!H20<>"",'Material Summary'!H20,"") -> 174336 | I41: =IF('Material Summary'!I20<>"",'Material Summary'!I20,"") -> 0.20458562
B42: =IF('Material Summary'!B21<>"",'Material Summary'!B21,"") -> Tiscon 10mm | C42: =IF('Material Summary'!C21<>"",'Material Summary'!C21,"") -> 200 | D42: =IF('Material Summary'!D21<>"",'Material Summary'!D21,"") -> Pcs | E42: =IF('Material Summary'!E21<>"",'Material Summary'!E21,"") -> 642 | F42: =IF('Material Summary'!F21<>"",'Material Summary'!F21,"") -> 128400 | G42: =IF('Material Summary'!G21<>"",'Material Summary'!G21,"") -> 5136 | H42: =IF('Material Summary'!H21<>"",'Material Summary'!H21,"") -> 123264 | I42: =IF('Material Summary'!I21<>"",'Material Summary'!I21,"") -> 0.14465195
B43: =IF('Material Summary'!B22<>"",'Material Summary'!B22,"") -> Tiscon 8mm | C43: =IF('Material Summary'!C22<>"",'Material Summary'!C22,"") -> 50 | D43: =IF('Material Summary'!D22<>"",'Material Summary'!D22,"") -> Pcs | E43: =IF('Material Summary'!E22<>"",'Material Summary'!E22,"") -> 420 | F43: =IF('Material Summary'!F22<>"",'Material Summary'!F22,"") -> 21000 | G43: =IF('Material Summary'!G22<>"",'Material Summary'!G22,"") -> 840 | H43: =IF('Material Summary'!H22<>"",'Material Summary'!H22,"") -> 20160 | I43: =IF('Material Summary'!I22<>"",'Material Summary'!I22,"") -> 0.023658029
B44: =IF('Material Summary'!B23<>"",'Material Summary'!B23,"") -> Tiscon 6mm | C44: =IF('Material Summary'!C23<>"",'Material Summary'!C23,"") -> 100 | D44: =IF('Material Summary'!D23<>"",'Material Summary'!D23,"") -> Pcs | E44: =IF('Material Summary'!E23<>"",'Material Summary'!E23,"") -> 246 | F44: =IF('Material Summary'!F23<>"",'Material Summary'!F23,"") -> 24600 | G44: =IF('Material Summary'!G23<>"",'Material Summary'!G23,"") -> 0 | H44: =IF('Material Summary'!H23<>"",'Material Summary'!H23,"") -> 24600 | I44: =IF('Material Summary'!I23<>"",'Material Summary'!I23,"") -> 0.028868428
B45: =IF('Material Summary'!B24<>"",'Material Summary'!B24,"") -> Wire 4mm | C45: =IF('Material Summary'!C24<>"",'Material Summary'!C24,"") -> 0 | D45: =IF('Material Summary'!D24<>"",'Material Summary'!D24,"") -> Bundle/Metres | E45: =IF('Material Summary'!E24<>"",'Material Summary'!E24,"") | F45: =IF('Material Summary'!F24<>"",'Material Summary'!F24,"") -> 0 | G45: =IF('Material Summary'!G24<>"",'Material Summary'!G24,"") -> 0 | H45: =IF('Material Summary'!H24<>"",'Material Summary'!H24,"") -> 0 | I45: =IF('Material Summary'!I24<>"",'Material Summary'!I24,"") -> 0

Sheet Master Data
A1: MASTER DATA — Categories, Vendors & Reference Lists
A2: Add new categories/vendors here. All dropdowns across sheets pull from these lists.
A4: CATEGORY | B4: SUB-CATEGORY | C4: UNIT | E4: VENDOR NAME | F4: VENDOR TYPE | G4: DEFAULT PAY MODE | I4: PAID BY | J4: PAYMENT MODE | K4: CONSTRUCTION PHASE | M4: SubCatList | N4: UnitList
A5: Building Materials | B5: Bricks | C5: Nos/Trailor | E5: Pappu Hardware | F5: Hardware/Steel | G5: GPay | I5: Self-GPay | J5: GPay | K5: Land Development | M5: Auto/Taxi | N5: Bags
A6: Building Materials | B6: Sand | C6: CFT | E6: Brick Company | F6: Bricks | G6: GPay | I6: Self-Paytm | J6: Paytm | K6: Foundation | M6: Bamboo/Shuttering | N6: Bundle/Metres
A7: Building Materials | B7: Concrete/Gitti | C7: Tonnes/Trailor | E7: Sand Truck Wala | F7: Sand | G7: GPay | I7: Self-Cash | J7: Cash | K7: Plinth | M7: Binding Wire | N7: CFT
A8: Building Materials | B8: Cement-Ultratech Super | C8: Bags | E8: Concrete Supplier | F8: Concrete/Gitti | G8: GPay/Paytm | I8: Self-Bank Transfer | J8: Bank Transfer | K8: Superstructure | M8: Blade | N8: Days
A9: Building Materials | B9: Cement-Ultratech Normal | C9: Bags | E9: Dinesh-Electrician | F9: Electrical Items | G9: GPay | I9: Through Sonbhai | J9: UPI | K9: Roof/Dhalai | M9: Boards/Plates | N9: Days/Lumpsum
A10: Building Materials | B10: Cement-Ultratech Prem | C10: Bags | E10: Mukesh Yadav | F10: Mitti Bharai/JCB | G10: GPay | I10: Through Engineer | J10: Cheque | K10: Electrical | M10: Bricks | N10: Kg
A11: Building Materials | B11: Dr Fixit | C11: Litres | E11: Chand Ansari | F11: Dhalai Machine | G11: GPay | I11: Through Ajay | K11: Plumbing | M11: Cement-Ultratech Normal | N11: Kg/Bags
A12: Building Materials | B12: Pipe PVC/GI | C12: Pcs | E12: Ajay Mahto | F12: Labour/Transport | G12: GPay | I12: Papa | K12: Plastering | M12: Cement-Ultratech Prem | N12: Litres
A13: Building Materials | B13: Cover Block | C13: Packets | E13: Mukhiya | F13: Bamboo/Misc | G13: Cash | I13: Chota Bhai | K13: Flooring | M13: Cement-Ultratech Super | N13: Lumpsum
A14: Building Materials | B14: Kala Panni/Tar | C14: Kg | E14: Sonbhai-Coordinator | F14: Labour Payments/Misc | G14: GPay | K14: Painting | M14: Concrete/Gitti | N14: Nos
A15: Building Materials | B15: Bamboo/Shuttering | C15: Nos | E15: Econ Builder | F15: Engineering/Labour | G15: GPay | K15: Finishing | M15: Conduit Pipe | N15: Nos/Trailor
A16: Building Materials | B16: Nails | C16: Kg/Bags | E16: Rinku Devi A/c | F16: Labour Account | G16: GPay | K16: Boundary Wall | M16: Cover Block | N16: Packets
A17: Building Materials | B17: Binding Wire | C17: Kg | E17: Naveen Hardware | F17: Cement/Building Materials | G17: Bank Transfer | M17: Daily Labour-Mitti Bharai | N17: Pcs
A18: Building Materials | B18: Blade | C18: Pcs | M18: Dhalai Machine Rent | N18: Tonnes/Trailor
A19: Steel/Iron | B19: Tiscon 16mm | C19: Pcs | M19: Dr Fixit | N19: Trips
A20: Steel/Iron | B20: Tiscon 12mm | C20: Pcs | M20: Engineer Labour Charge | N20: Visit
A21: Steel/Iron | B21: Tiscon 10mm | C21: Pcs | M21: Engineer Visit Charge
A22: Steel/Iron | B22: Tiscon 8mm | C22: Pcs | M22: Fan Hooks/Holders
A23: Steel/Iron | B23: Tiscon 6mm | C23: Pcs | M23: Junction/Bend/Fitting
A24: Electrical | B24: Wire 4mm | C24: Bundle/Metres | M24: Kala Panni/Tar
A25: Electrical | B25: Wire 2.5mm | C25: Bundle/Metres | M25: Labour Food-Rice/Wheat/Gas
A26: Electrical | B26: Wire 1.5mm | C26: Bundle/Metres | M26: Ladies Labour-Bricks
A27: Electrical | B27: Wire 1mm | C27: Bundle/Metres | M27: Land Levelling/Filling
A28: Electrical | B28: Wire 0.75mm | C28: Bundle/Metres | M28: MCB/Distribution Board
A29: Electrical | B29: Switches/Sockets | C29: Pcs | M29: Map/Drawing Charge
A30: Electrical | B30: MCB/Distribution Board | C30: Pcs | M30: Nails
A31: Electrical | B31: Conduit Pipe | C31: Pcs | M31: Pipe PVC/GI
A32: Electrical | B32: Fan Hooks/Holders | C32: Pcs | M32: Sand
... A48: Miscellaneous | B48: Tools/Consumables | C48: Lumpsum | M48: Wire 4mm

Sheet All Transactions
A1: HOME CONSTRUCTION — EXPENSE REGISTER
A2: Enter every payment/expense as one row. Blue cells = input. Black cells = auto-calculated formulas.
A4: Sr No | B4: Date | C4: Month | D4: Construction Phase | E4: Category | F4: Sub-Category | G4: Item Description | H4: Vendor/Paid To | I4: Qty | J4: Unit | K4: Rate ₹ | L4: Gross Amt ₹ | M4: Discount % | N4: Discount amount | O4: Net Amt ₹ | P4: Paid By | Q4: Payment Mode
A5: 1 | B5: 46149 | C5: =IF(B5="","",TEXT(B5,"MMM-YYYY")) -> May-2026 | D5: Foundation | E5: Professional Fees | F5: Engineer Visit Charge | G5: Advance to Engineer | H5: Econ Builder | I5: 1 | J5: Lumpsum | K5: 5000 | L5: =IF(OR(I5="",K5=""),"",I5*K5) -> 5000 | N5: =M5*L5 -> 0 | O5: =IF(L5="","",IF(M5="",L5,L5*(1-M5))) -> 5000 | P5: Papa | Q5: GPay
A6: 2 | B6: 46149 | C6: =IF(B6="","",TEXT(B6,"MMM-YYYY")) -> May-2026 | D6: Land Development | E6: Labour | F6: Daily Labour-Mitti Bharai | G6: Site cleaning by Chanarveer (adhoc labour) | H6: Sonbhai-Coordinator | I6: 1 | J6: Lumpsum | K6: 1500 | L6: =IF(OR(I6="",K6=""),"",I6*K6) -> 1500 | N6: =M6*L6 -> 0 | O6: =IF(L6="","",IF(M6="",L6,L6*(1-M6))) -> 1500 | P6: Self-GPay | Q6: GPay
A7: 3 | B7: 46153 | C7: =IF(B7="","",TEXT(B7,"MMM-YYYY")) -> May-2026 | D7: Foundation | E7: Building Materials | F7: Cement-Ultratech Super | G7: Bill 63 - Ultratech Super 40 bags | H7: Pappu Hardware | I7: 40 | J7: Bags | K7: 360 | L7: =IF(OR(I7="",K7=""),"",I7*K7) -> 14400 | N7: =M7*L7 -> 0 | O7: =IF(L7="","",IF(M7="",L7,L7*(1-M7))) -> 14400 | P7: Self-GPay | Q7: GPay
A8: 4 | B8: 46153 | C8: =IF(B8="","",TEXT(B8,"MMM-YYYY")) -> May-2026 | D8: Foundation | E8: Steel/Iron | F8: Tiscon 12mm | G8: Bill 63 - Tiscon 12mm 100pcs | H8: Pappu Hardware | I8: 100 | J8: Pcs | K8: 908 | L8: =IF(OR(I8="",K8=""),"",I8*K8) -> 90800 | M8: 0.04 | N8: =M8*L8 -> 3632 | O8: =IF(L8="","",IF(M8="",L8,L8*(1-M8))) -> 87168 | P8: Self-GPay | Q8: GPay
A9: 5 | B9: 46153 | C9: =IF(B9="","",TEXT(B9,"MMM-YYYY")) -> May-2026 | D9: Foundation | E9: Steel/Iron | F9: Tiscon 10mm | G9: Bill 63 - Tiscon 10mm 100pcs | H9: Pappu Hardware | I9: 100 | J9: Pcs | K9: 642 | L9: =IF(OR(I9="",K9=""),"",I9*K9) -> 64200 | M9: 0.04 | N9: =M9*L9 -> 2568 | O9: =IF(L9="","",IF(M9="",L9,L9*(1-M9))) -> 61632 | P9: Self-GPay | Q9: GPay
A10: 6 | B10: 46153 | C10: =IF(B10="","",TEXT(B10,"MMM-YYYY")) -> May-2026 | D10: Foundation | E10: Steel/Iron | F10: Tiscon 6mm | G10: Bill 63 - Tiscon 6mm 50pcs | H10: Pappu Hardware | I10: 50 | J10: Pcs | K10: 246 | L10: =IF(OR(I10="",K10=""),"",I10*K10) -> 12300 | N10: =M10*L10 -> 0 | O10: =IF(L10="","",IF(M10="",L10,L10*(1-M10))) -> 12300 | P10: Self-GPay | Q10: GPay
A11: 7 | B11: 46153 | C11: =IF(B11="","",TEXT(B11,"MMM-YYYY")) -> May-2026 | D11: Foundation | E11: Building Materials | F11: Binding Wire | G11: Bill 63 - Binding Wire 20kg | H11: Pappu Hardware | I11: 20 | J11: Kg | K11: 120 | L11: =IF(OR(I11="",K11=""),"",I11*K11) -> 2400 | N11: =M11*L11 -> 0 | O11: =IF(L11="","",IF(M11="",L11,L11*(1-M11))) -> 2400 | P11: Self-GPay | Q11: GPay
A12: 8 | B12: 46153 | C12: =IF(B12="","",TEXT(B12,"MMM-YYYY")) -> May-2026 | D12: Foundation | E12: Building Materials | F12: Dr Fixit | G12: Bill 63 - Dr Fixit 10L x 2pcs | H12: Pappu Hardware | I12: 2 | J12: Litres | K12: 1400 | L12: =IF(OR(I12="",K12=""),"",I12*K12) -> 2800 | N12: =M12*L12 -> 0 | O12: =IF(L12="","",IF(M12="",L12,L12*(1-M12))) -> 2800 | P12: Self-GPay | Q12: GPay
A13: 9 | B13: 46153 | C13: =IF(B13="","",TEXT(B13,"MMM-YYYY")) -> May-2026 | D13: Foundation | E13: Transport | F13: Truck/Tempo Freight | G13: Bill 63 - Transport from Pappu Hardware | H13: Pappu Hardware | I13: 1 | J13: Trips | K13: 250 | L13: =IF(OR(I13="",K13=""),"",I13*K13) -> 250 | N13: =M13*L13 -> 0 | O13: =IF(L13="","",IF(M13="",L13,L13*(1-M13))) -> 250 | P13: Self-GPay | Q13: GPay
A14: 10 | B14: 46153 | C14: =IF(B14="","",TEXT(B14,"MMM-YYYY")) -> May-2026 | D14: Foundation | E14: Labour | F14: Skilled Labour | G14: Bill 63 - Loading labour | H14: Pappu Hardware | I14: 1 | J14: Lumpsum | K14: 450 | L14: =IF(OR(I14="",K14=""),"",I14*K14) -> 450 | N14: =M14*L14 -> 0 | O14: =IF(L14="","",IF(M14="",L14,L14*(1-M14))) -> 450 | P14: Self-GPay | Q14: GPay
A15: 11 | B15: 46153 | C15: =IF(B15="","",TEXT(B15,"MMM-YYYY")) -> May-2026 | D15: Foundation | E15: Building Materials | F15: Nails | G15: Bill 63 - Kanti (Nails) 2"x1" 1 bag | H15: Pappu Hardware | I15: 1 | J15: Kg/Bags | K15: 2000 | L15: =IF(OR(I15="",K15=""),"",I15*K15) -> 2000 | N15: =M15*L15 -> 0 | O15: =IF(L15="","",IF(M15="",L15,L15*(1-M15))) -> 2000 | P15: Self-GPay | Q15: GPay
A16: 12 | B16: 46153 | C16: =IF(B16="","",TEXT(B16,"MMM-YYYY")) -> May-2026 | D16: Foundation | E16: Building Materials | F16: Nails | G16: Bill 63 - Additional discount from Pappu Hardware | H16: Pappu Hardware | I16: 1 | J16: Lumpsum | K16: -400 | L16: =IF(OR(I16="",K16=""),"",I16*K16) -> -400 | N16: =M16*L16 -> 0 | O16: =IF(L16="","",IF(M16="",L16,L16*(1-M16))) -> -400 | P16: Self-GPay | Q16: GPay
A17: 13 | B17: 46154 | C17: =IF(B17="","",TEXT(B17,"MMM-YYYY")) -> May-2026 | D17: Land Development | E17: Land Development | F17: Land Levelling/Filling | G17: JCB work 17.5 hrs @ ₹1,000/hr | H17: Mukesh Yadav | I17: 17.5 | J17: Hrs | K17: 1000 | L17: 17500 | N17: =M17*L17 -> 0 | O17: =IF(L17="","",IF(M17="",L17,L17*(1-M17))) -> 17500 | P17: Papa | Q17: GPay
A18: 14 | B18: 46146 | C18: =IF(B18="","",TEXT(B18,"MMM-YYYY")) -> May-2026 | D18: Foundation | E18: Building Materials | F18: Sand | G18: Sand 1st truck (920 CFT) | H18: Sand Truck Wala | I18: 920 | J18: CFT | K18: 55000 | L18: 55000 | N18: =M18*L18 -> 0 | O18: =IF(L18="","",IF(M18="",L18,L18*(1-M18))) -> 55000 | P18: Papa | Q18: GPay
A19: 15 | B19: 46154 | C19: =IF(B19="","",TEXT(B19,"MMM-YYYY")) -> May-2026 | D19: Foundation | E19: Building Materials | F19: Sand | G19: Sand 2nd truck (918 CFT) | H19: Sand Truck Wala | I19: 918 | J19: CFT | K19: 55000 | L19: 55000 | N19: =M19*L19 -> 0 | O19: =IF(L19="","",IF(M19="",L19,L19*(1-M19))) -> 55000 | P19: Papa | Q19: GPay
A20: 16 | B20: 46156 | C20: May-2026 | D20: Foundation | E20: Building Materials | F20: Bricks | G20: Bricks - tractor 1 delivery (1500 pcs) | H20: Brick Company | I20: 1500 | J20: Nos | K20: 8.5 | L20: 12750 | O20: =IF(L20="","",IF(M20="",L20,L20*(1-M20))) -> 12750 | P20: Self-GPay | Q20: GPay
A21: 17 | B21: 46157 | C21: May-2026 | D21: Foundation | E21: Building Materials | F21: Concrete/Gitti | G21: Crushed stone / Gitti - 27.5 Ton (600 CFT) | H21: Concrete Supplier | I21: 27.5 | J21: Ton | K21: 2400 | L21: 66000 | O21: =IF(L21="","",IF(M21="",L21,L21*(1-M21))) -> 66000 | P21: Papa | Q21: GPay
A22: 18 | B22: 46157 | C22: May-2026 | D22: Foundation | E22: Professional Fees | F22: Engineering | G22: Layout mapping / Naksha by Econ Builder | H22: Econ Builder | I22: 1 | J22: Lumpsum | K22: 11000 | L22: 11000 | O22: =IF(L22="","",IF(M22="",L22,L22*(1-M22))) -> 11000 | P22: Papa | Q22: GPay
A23: 19 | B23: 46158 | C23: May-2026 | D23: Foundation | E23: Professional Fees | F23: Engineering | G23: Engineer advance to Econ Builder (construction supervision) | H23: Econ Builder | I23: 1 | J23: Lumpsum | K23: 50000 | L23: 50000 | O23: =IF(L23="","",IF(M23="",L23,L23*(1-M23))) -> 50000 | P23: Self-GPay | Q23: GPay
A24: 20 | B24: 46157 | C24: May-2026 | D24: Foundation | E24: Building Materials | F24: Bricks | G24: Bricks - tractor 2 delivery (1500 pcs) | H24: Brick Company | I24: 1500 | J24: Nos | K24: 8.5 | L24: 12750 | O24: =IF(L24="","",IF(M24="",L24,L24*(1-M24))) -> 12750 | P24: Self-GPay | Q24: GPay
A25: 21 | B25: 46157 | C25: May-2026 | D25: Foundation | E25: Building Materials | F25: Bricks | G25: Bricks - tractor 3 delivery (1500 pcs) | H25: Brick Company | I25: 1500 | J25: Nos | K25: 8.5 | L25: 12750 | O25: =IF(L25="","",IF(M25="",L25,L25*(1-M25))) -> 12750 | P25: Self-GPay | Q25: GPay
A26: 22 | B26: 46157 | C26: May-2026 | D26: Foundation | E26: Building Materials | F26: Bricks | G26: Bricks - tractor 4 delivery (1500 pcs) | H26: Brick Company | I26: 1500 | J26: Nos | K26: 8.5 | L26: 12750 | O26: =IF(L26="","",IF(M26="",L26,L26*(1-M26))) -> 12750 | P26: Self-GPay | Q26: GPay
A27: 23 | B27: 46157 | C27: May-2026 | D27: Foundation | E27: Building Materials | F27: Bricks | G27: Bricks - tractor 5 delivery (1500 pcs) | H27: Brick Company | I27: 1500 | J27: Nos | K27: 8.5 | L27: 12750 | O27: =IF(L27="","",IF(M27="",L27,L27*(1-M27))) -> 12750 | P27: Self-GPay | Q27: GPay
A28: 24 | B28: 46158 | C28: May-2026 | D28: Foundation | E28: Miscellaneous | F28: Kala Panni/Tar | G28: Polythene / Panni | H28: Local Purchase | I28: 1 | J28: Lumpsum | K28: 600 | L28: 600 | O28: =IF(L28="","",IF(M28="",L28,L28*(1-M28))) -> 600 | P28: Papa | Q28: GPay
A29: 25 | B29: 46158 | C29: May-2026 | D29: Foundation | E29: Miscellaneous | F29: Tools/Equipment | G29: Construction equipment - Tegadi & Kudal | H29: Local Purchase | I29: 1 | J29: Lumpsum | K29: 1175 | L29: 1175 | O29: =IF(L29="","",IF(M29="",L29,L29*(1-M29))) -> 1175 | P29: Papa | Q29: GPay
A30: 26 | B30: 46158 | C30: May-2026 | D30: Foundation | E30: Food/Provisions | F30: Food/Ration | G30: Food ration for labour | H30: Local Purchase | I30: 1 | J30: Lumpsum | K30: 3285 | L30: 3285 | O30: =IF(L30="","",IF(M30="",L30,L30*(1-M30))) -> 3285 | P30: Papa | Q30: GPay
A31: 27 | B31: 46161 | C31: May-2026 | D31: Foundation | E31: Building Materials | F31: Binding Wire | G31: Soft wire | H31: Pappu Hardware | I31: 1 | J31: Lumpsum | K31: 1300 | L31: 1300 | O31: =IF(L31="","",IF(M31="",L31,L31*(1-M31))) -> 1300 | P31: Self-GPay | Q31: GPay
... A47: 43 | B47: 46166 | C47: May-2026 | D47: Plinth | E47: Building Materials | F47: Bricks | G47: Bricks - tractor 9 delivery (1500 pcs) | H47: Brick Company | I47: 1500 | J47: Nos | K47: 8.5 | L47: 12750 | O47: =IF(L47="","",IF(M47="",L47,L47*(1-M47))) -> 12750 | P47: Self-GPay | Q47: GPay
A48: 44 | B48: 46167 | C48: May-2026 | D48: Plinth | E48: Professional Fees | F48: Engineering | G48: Engineer payment to Econ Builder | H48: Econ Builder | I48: 1 | J48: Lumpsum | K48: 10000 | L48: 10000 | N48: =IF(L48="","",IF(M48="",0,L48*M48)) -> 0 | O48: =IF(L48="","",IF(M48="",L48,L48*(1-M48))) -> 10000 | P48: Papa | Q48: GPay
A49: 45 | B49: 46167 | C49: May-2026 | D49: Plinth | E49: Building Materials | F49: Bricks | G49: Bricks - tractor 10 delivery (1500 pcs) | H49: Brick Company | I49: 1500 | J49: Nos | K49: 8.5 | L49: 12750 | N49: =IF(L49="","",IF(M49="",0,L49*M49)) -> 0 | O49: =IF(L49="","",IF(M49="",L49,L49*(1-M49))) -> 12750 | P49: Self-GPay | Q49: GPay
A50: 46 | B50: 46168 | C50: May-2026 | D50: Plinth | E50: Building Materials | F50: Bricks | G50: Bricks - tractor 11 delivery (1500 pcs) | H50: Brick Company | I50: 1500 | J50: Nos | K50: 8.5 | L50: 12750 | N50: =IF(L50="","",IF(M50="",0,L50*M50)) -> 0 | O50: =IF(L50="","",IF(M50="",L50,L50*(1-M50))) -> 12750 | P50: Self-GPay | Q50: GPay
A51: 47 | B51: 46168 | C51: May-2026 | D51: Plinth | E51: Building Materials | F51: Bricks | G51: Bricks - tractor 12 delivery (1500 pcs) | H51: Brick Company | I51: 1500 | J51: Nos | K51: 8.5 | L51: 12750 | N51: =IF(L51="","",IF(M51="",0,L51*M51)) -> 0 | O51: =IF(L51="","",IF(M51="",L51,L51*(1-M51))) -> 12750 | P51: Self-GPay | Q51: GPay
A52: 48 | B52: 46168 | C52: May-2026 | D52: Plinth | E52: Land Development | F52: Land Levelling/Filling | G52: Mitti filling - 22 trailers @ ₹600 each | H52: Mukesh Yadav | I52: 22 | J52: Nos | K52: 600 | L52: 13200 | N52: =IF(L52="","",IF(M52="",0,L52*M52)) -> 0 | O52: =IF(L52="","",IF(M52="",L52,L52*(1-M52))) -> 13200 | P52: Papa | Q52: GPay
A53: 49 | B53: 46174 | C53: Jun-2026 | D53: Plinth | E53: Steel/Iron | F53: Tiscon 12mm | G53: Tiscon 12mm TMT - 100 PC @ ₹908 (Bill 2) | H53: Pappu Hardware | I53: 100 | J53: Pcs | K53: 908 | L53: 90800 | M53: 0.04 | N53: =IF(L53="","",IF(M53="",0,L53*M53)) -> 3632 | O53: =IF(L53="","",IF(M53="",L53,L53*(1-M53))) -> 87168 | P53: Self-Bank Transfer | Q53: Bank Transfer
A54: 50 | B54: 46174 | C54: Jun-2026 | D54: Plinth | E54: Steel/Iron | F54: Tiscon 10mm | G54: Tiscon 10mm TMT - 100 PC @ ₹642 (Bill 2) | H54: Pappu Hardware | I54: 100 | J54: Pcs | K54: 642 | L54: 64200 | M54: 0.04 | N54: =IF(L54="","",IF(M54="",0,L54*M54)) -> 2568 | O54: =IF(L54="","",IF(M54="",L54,L54*(1-M54))) -> 61632 | P54: Self-Bank Transfer | Q54: Bank Transfer
A55: 51 | B55: 46174 | C55: Jun-2026 | D55: Plinth | E55: Steel/Iron | F55: Tiscon 8mm | G55: Tiscon 8mm TMT - 50 PC @ ₹420 (NEW) | H55: Pappu Hardware | I55: 50 | J55: Pcs | K55: 420 | L55: 21000 | M55: 0.04 | N55: =IF(L55="","",IF(M55="",0,L55*M55)) -> 840 | O55: =IF(L55="","",IF(M55="",L55,L55*(1-M55))) -> 20160 | P55: Self-Bank Transfer | Q55: Bank Transfer
A56: 52 | B56: 46174 | C56: Jun-2026 | D56: Plinth | E56: Steel/Iron | F56: Tiscon 6mm | G56: Tiscon 6mm TMT - 50 PC @ ₹246 (Bill 2) | H56: Pappu Hardware | I56: 50 | J56: Pcs | K56: 246 | L56: 12300 | N56: =IF(L56="","",IF(M56="",0,L56*M56)) -> 0 | O56: =IF(L56="","",IF(M56="",L56,L56*(1-M56))) -> 12300 | P56: Self-Bank Transfer | Q56: Bank Transfer
...

Sheet Bill Entry
A1: VENDOR BILL / INVOICE — LINE ENTRY
A2: When a paper bill arrives, enter each line item here. Same Bill No groups items of one bill.
A4: Bill No | B4: Bill Date | C4: Vendor | D4: Category | E4: Sub-Category | F4: Item Description | G4: HSN/SAC | H4: Qty | I4: Unit | J4: Rate ₹ | K4: Line Amt ₹ | L4: Discount/Adj ₹ | M4: Transport ₹ | N4: Labour Charge ₹ | O4: Bill Total ₹
A5: 63 | B5: 46153 | C5: Pappu Hardware | D5: Building Materials | E5: Cement-Ultratech Super | F5: Ultratech Super Cement | H5: 40 | I5: Bags | J5: 360 | K5: =IF(OR(H5="",J5=""),"",H5*J5) -> 14400 | O5: =IF(K5="","",K5-IF(L5="",0,L5)+IF(M5="",0,M5)+IF(N5="",0,N5)) -> 14400
A6: 63 | B6: 46153 | C6: Pappu Hardware | D6: Steel/Iron | E6: Tiscon 12mm | F6: Tiscon 12mm | H6: 100 | I6: Pcs | J6: 908 | K6: =IF(OR(H6="",J6=""),"",H6*J6) -> 90800 | O6: =IF(K6="","",K6-IF(L6="",0,L6)+IF(M6="",0,M6)+IF(N6="",0,N6)) -> 90800
A7: 63 | B7: 46153 | C7: Pappu Hardware | D7: Steel/Iron | E7: Tiscon 10mm | F7: Tiscon 10mm | H7: 100 | I7: Pcs | J7: 642 | K7: =IF(OR(H7="",J7=""),"",H7*J7) -> 64200 | O7: =IF(K7="","",K7-IF(L7="",0,L7)+IF(M7="",0,M7)+IF(N7="",0,N7)) -> 64200
A8: 63 | B8: 46153 | C8: Pappu Hardware | D8: Steel/Iron | E8: Tiscon 6mm | F8: Tiscon 6mm | H8: 50 | I8: Pcs | J8: 246 | K8: =IF(OR(H8="",J8=""),"",H8*J8) -> 12300 | O8: =IF(K8="","",K8-IF(L8="",0,L8)+IF(M8="",0,M8)+IF(N8="",0,N8)) -> 12300
A9: 63 | B9: 46153 | C9: Pappu Hardware | D9: Building Materials | E9: Binding Wire | F9: Binding Wire 20kg | H9: 20 | I9: Kg | J9: 600 | K9: =IF(OR(H9="",J9=""),"",H9*J9) -> 12000 | O9: =IF(K9="","",K9-IF(L9="",0,L9)+IF(M9="",0,M9)+IF(N9="",0,N9)) -> 12000
A10: 63 | B10: 46153 | C10: Pappu Hardware | D10: Building Materials | E10: Dr Fixit | F10: Dr Fixit 10L x 2pcs | H10: 2 | I10: Litres | J10: 1400 | K10: =IF(OR(H10="",J10=""),"",H10*J10) -> 2800 | O10: =IF(K10="","",K10-IF(L10="",0,L10)+IF(M10="",0,M10)+IF(N10="",0,N10)) -> 2800
A11: 63 | B11: 46153 | C11: Pappu Hardware | D11: Transport | E11: Truck/Tempo Freight | F11: Transport | H11: 1 | I11: Trips | J11: 250 | K11: =IF(OR(H11="",J11=""),"",H11*J11) -> 250 | O11: =IF(K11="","",K11-IF(L11="",0,L11)+IF(M11="",0,M11)+IF(N11="",0,N11)) -> 250
A12: 63 | B12: 46153 | C12: Pappu Hardware | D12: Labour | E12: Skilled Labour | F12: Loading labour | H12: 1 | I12: Lumpsum | J12: 450 | K12: =IF(OR(H12="",J12=""),"",H12*J12) -> 450 | O12: =IF(K12="","",K12-IF(L12="",0,L12)+IF(M12="",0,M12)+IF(N12="",0,N12)) -> 450
A13: 63 | B13: 46153 | C13: Pappu Hardware | D13: Building Materials | E13: Nails | F13: Kanti (Nails) 2"x1" - 1 bag | H13: 1 | I13: Kg/Bags | J13: 2000 | K13: =IF(OR(H13="",J13=""),"",H13*J13) -> 2000 | O13: =IF(K13="","",K13-IF(L13="",0,L13)+IF(M13="",0,M13)+IF(N13="",0,N13)) -> 2000
K14: =IF(OR(H14="",J14=""),"",H14*J14) | O14: =IF(K14="","",K14-IF(L14="",0,L14)+IF(M14="",0,M14)+IF(N14="",0,N14))
K15: =IF(OR(H15="",J15=""),"",H15*J15) | O15: =IF(K15="","",K15-IF(L15="",0,L15)+IF(M15="",0,M15)+IF(N15="",0,N15))
K16: =IF(OR(H16="",J16=""),"",H16*J16) | O16: =IF(K16="","",K16-IF(L16="",0,L16)+IF(M16="",0,M16)+IF(N16="",0,N16))
K17: =IF(OR(H17="",J17=""),"",H17*J17) | O17: =IF(K17="","",K17-IF(L17="",0,L17)+IF(M17="",0,M17)+IF(N17="",0,N17))
K18: =IF(OR(H18="",J18=""),"",H18*J18) | O18: =IF(K18="","",K18-IF(L18="",0,L18)+IF(M18="",0,M18)+IF(N18="",0,N18))
K19: =IF(OR(H19="",J19=""),"",H19*J19) | O19: =IF(K19="","",K19-IF(L19="",0,L19)+IF(M19="",0,M19)+IF(N19="",0,N19))
K20: =IF(OR(H20="",J20=""),"",H20*J20) | O20: =IF(K20="","",K20-IF(L20="",0,L20)+IF(M20="",0,M20)+IF(N20="",0,N20))
K21: =IF(OR(H21="",J21=""),"",H21*J21) | O21: =IF(K21="","",K21-IF(L21="",0,L21)+IF(M21="",0,M21)+IF(N21="",0,N21))
K22: =IF(OR(H22="",J22=""),"",H22*J22) | O22: =IF(K22="","",K22-IF(L22="",0,L22)+IF(M22="",0,M22)+IF(N22="",0,N22))
K23: =IF(OR(H23="",J23=""),"",H23*J23) | O23: =IF(K23="","",K23-IF(L23="",0,L23)+IF(M23="",0,M23)+IF(N23="",0,N23))
K24: =IF(OR(H24="",J24=""),"",H24*J24) | O24: =IF(K24="","",K24-IF(L24="",0,L24)+IF(M24="",0,M24)+IF(N24="",0,N24))
K25: =IF(OR(H25="",J25=""),"",H25*J25) | O25: =IF(K25="","",K25-IF(L25="",0,L25)+IF(M25="",0,M25)+IF(N25="",0,N25))
... K504: =IF(OR(H504="",J504=""),"",H504*J504) | O504: =IF(K504="","",K504-IF(L504="",0,L504)+IF(M504="",0,M504)+IF(N504="",0,N504))

Sheet Payment Tracker
A1: PAYMENT TRACKER — Full Audit Trail
A2: Track every payment: who paid, to whom, how, reference number.
A4: Sr No | B4: Date | C4: Paid By | D4: Paid To (Vendor) | E4: Category | F4: Purpose/Description | G4: Amount ₹ | H4: Payment Mode | I4: UPI/Txn Ref | J4: Phone No | K4: Receipt Y/N | L4: Running Total ₹ | M4: Remarks
A5: 1 | B5: 46149 | C5: Papa | D5: Econ Builder | E5: Professional Fees | F5: Advance to Engineer for new construction | G5: 5000 | H5: GPay | K5: Pending | L5: =IF(G5="","",G5) -> 5000 | M5: First advance payment
A6: 2 | B6: 46149 | C6: Self-GPay | D6: Sonbhai-Coordinator | E6: Labour | F6: Chanarveer - adhoc labour site cleaning | G6: 1500 | H6: GPay | K6: No | L6: =IF(G6="","",IF(L5="",G6,L5+G6)) -> 6500 | M6: Adhoc daily labour
A7: 3 | B7: 46153 | C7: Self-GPay | D7: Pappu Hardware | E7: Building Materials | F7: Bill 63 - Part payment 1 of 2 (Cement+Steel+Wire+DrFixit+Nails) | G7: 90000 | H7: GPay | K7: No | L7: =IF(G7="","",IF(L6="",G7,L6+G7)) -> 96500 | M7: Balance ₹93,000 to be paid 12-May
A8: 4 | B8: 46155 | C8: Self-GPay | D8: Pappu Hardware | E8: Building Materials | F8: Bill 63 - Part payment 2 of 2 (Final, incl ₹400 extra discount) | G8: 93000 | H8: GPay | K8: Pending | L8: =IF(G8="","",IF(L7="",G8,L7+G8)) -> 189500 | M8: Bill 63 fully settled. Total paid ₹1,83,000 against bill ₹1,83,400 (₹400 additional discount)
A9: 5 | B9: 46154 | C9: Papa | D9: Mukesh Yadav | E9: Land Development | F9: JCB work 17 hrs @ ₹1,000/hr - Advance payment | G9: 5000 | H9: GPay | K9: No | L9: =IF(G9="","",IF(L8="",G9,L8+G9)) -> 194500 | M9: Total JCB bill ₹17,000. Balance ₹12,000 pending
A10: 6 | B10: 46146 | C10: Papa | D10: Sand Truck Wala | E10: Building Materials | F10: Sand 1st truck (920 CFT) - Full payment | G10: 55000 | H10: GPay | K10: No | L10: =IF(G10="","",IF(L9="",G10,L9+G10)) -> 249500 | M10: Paid in full
A11: 7 | B11: 46154 | C11: Papa | D11: Sand Truck Wala | E11: Building Materials | F11: Sand 2nd truck (918 CFT) - Full payment | G11: 55000 | H11: GPay | K11: No | L11: =IF(G11="","",IF(L10="",G11,L10+G11)) -> 304500 | M11: Paid in full
A12: 8 | B12: 46156 | C12: Self-GPay | D12: Brick Company | E12: Building Materials | F12: Brick advance - Self share (₹2L of ₹3.69L total) | G12: 200000 | H12: GPay | K12: N | L12: =L11+G12 -> 504500 | M12: Part of ₹3,69,000 total brick advance
A13: 9 | B13: 46156 | C13: Chota Bhai | D13: Brick Company | E13: Building Materials | F13: Brick advance - Chota Bhai share | G13: 169000 | H13: GPay | K13: N | L13: =IF(G13="","",IF(L12="",G13,L12+G13)) -> 673500 | M13: Part of ₹3,69,000 total brick advance
A14: 10 | B14: 46157 | C14: Papa | D14: Concrete Supplier | E14: Building Materials | F14: Crushed stone / Gitti 600 CFT - Full payment | G14: 66000 | H14: GPay | K14: N | L14: =IF(G14="","",IF(L13="",G14,L13+G14)) -> 739500 | M14: Paid in full
A15: 11 | B15: 46157 | C15: Papa | D15: Econ Builder | E15: Professional Fees | F15: Layout mapping / Naksha | G15: 11000 | H15: GPay | K15: N | L15: =IF(G15="","",IF(L14="",G15,L14+G15)) -> 750500 | M15: Layout mapping payment
A16: 12 | B16: 46158 | C16: Self-GPay | D16: Econ Builder | E16: Professional Fees | F16: Engineer advance for construction supervision | G16: 50000 | H16: GPay | K16: N | L16: =IF(G16="","",IF(L15="",G16,L15+G16)) -> 800500 | M16: Engineer advance
A17: 13 | B17: 46158 | C17: Papa | D17: Local Purchase | E17: Miscellaneous | F17: Panni ₹600 + Tegadi/Kudal ₹1,175 + Food ration ₹3,285 | G17: 5060 | H17: GPay | K17: N | L17: =IF(G17="","",IF(L16="",G17,L16+G17)) -> 805560 | M17: Misc site purchases
A18: 14 | B18: 46161 | C18: Self-GPay | D18: Pappu Hardware | E18: Building Materials | F18: Soft wire ₹1,300 + Cover blocks 6×₹350 + Labour ₹100 | G18: 3500 | H18: GPay | K18: N | L18: =IF(G18="","",IF(L17="",G18,L17+G18)) -> 809060 | M18: Wire + cover blocks + labour
A19: 15 | B19: 46163 | C19: Self-GPay | D19: Pappu Hardware | E19: Building Materials | F19: Cement 60bags ₹21,600 + Transport ₹250 + Labour ₹250 + Metal sheet ₹2,700 | G19: 24800 | H19: GPay | K19: N | L19: =IF(G19="","",IF(L18="",G19,L18+G19)) -> 833860 | M19: Cement + transport + labour + metal sheet
A20: 16 | B20: 46164 | C20: Self-Bank Transfer | D20: Econ Builder | E20: Professional Fees | F20: Engineer advance - Net Banking | G20: 50000 | H20: Bank Transfer | K20: N | L20: =IF(G20="","",IF(L19="",G20,L19+G20)) -> 883860 | M20: Net banking transfer
A21: 17 | B21: 46165 | C21: Self-GPay | D21: Concrete Supplier | E21: Building Materials | F21: Gitti 37.64 Ton @ ₹2,550/ton | G21: 95982 | H21: GPay | K21: N | L21: =IF(G21="","",IF(L20="",G21,L20+G21)) -> 979842 | M21: Gitti 2nd delivery
A22: 18 | B22: 46167 | C22: Self-Bank Transfer | D22: Naveen Hardware | E22: Building Materials | F22: Cement 50 bags ₹18,000 + Transport ₹300 + Labour ₹350 | G22: 18650 | H22: Bank Transfer | K22: N | L22: =IF(G22="","",IF(L21="",G22,L21+G22)) -> 998492 | M22: New vendor - Naveen Hardware, Net Banking
A23: 19 | B23: 46167 | C23: Papa | D23: Econ Builder | E23: Professional Fees | F23: Engineer payment | G23: 10000 | H23: GPay | K23: N | L23: =IF(G23="","",IF(L22="",G23,L22+G23)) -> 1008492 | M23: Papa to Econ Builder
A24: 20 | B24: 46174 | C24: Self-Bank Transfer | D24: Pappu Hardware | E24: Steel/Iron + Building Materials | F24: Bill 2: Steel 12/10/8/6mm + Cement 50bags + Dr Fixit 20L + Transport + Labour | G24: 202830 | H24: Bank Transfer | K24: N | L24: =IF(G24="","",IF(L23="",G24,L23+G24)) -> 1211322 | M24: Pappu Hardware Bill 2 - Net Banking
... A26: 22 | B26: 46174 | C26: Self-GPay | D26: Econ Builder | E26: Professional Fees | F26: Engineer payment ₹1L | G26: 100000 | H26: GPay | K26: N | L26: =IF(G26="","",IF(L25="",G26,L25+G26)) -> 1334422 | M26: Self to Econ Builder
A27: 23 | L27: =IF(G27="","",IF(L26="",G27,L26+G27))
A28: 24 | L28: =IF(G28="","",IF(L27="",G28,L27+G28))
A29: 25 | L29: =IF(G29="","",IF(L28="",G29,L28+G29))
A30: 26 | L30: =IF(G30="","",IF(L29="",G30,L29+G30))
A31: 27 | L31: =IF(G31="","",IF(L30="",G31,L30+G31))
A32: 28 | L32: =IF(G32="","",IF(L31="",G32,L31+G32))
A33: 29 | L33: =IF(G33="","",IF(L32="",G33,L32+G33))
A34: 30 | L34: =IF(G34="","",IF(L33="",G34,L33+G34))
A35: 31 | L35: =IF(G35="","",IF(L34="",G35,L34+G35))
A36: 32 | L36: =IF(G36="","",IF(L35="",G36,L35+G36))
A37: 33 | L37: =IF(G37="","",IF(L36="",G37,L36+G37))
A38: 34 | L38: =IF(G38="","",IF(L37="",G38,L37+G38))
... A504: 500 | L504: =IF(G504="","",IF(L503="",G504,L503+G504))

Sheet Material Summary
A1: MATERIAL PURCHASE SUMMARY
A2: Auto-calculated from All Transactions using SUMIFS. No manual entry needed.
A4: Category | B4: Sub-Category | C4: Total Qty | D4: Unit | E4: Avg Rate ₹ | F4: Total Gross ₹ | G4: Total Discount ₹ | H4: Total Net ₹ | I4: % of Total
A5: Building Materials | B5: Bricks | C5: =SUMIFS('All Transactions'!I:I,'All Transactions'!E:E,A5,'All Transactions'!F:F,B5) -> 18000 | D5: Nos/Trailor | E5: =IFERROR(F5/C5,"") -> 8.5 | F5: =SUMIFS('All Transactions'!L:L,'All Transactions'!E:E,A5,'All Transactions'!F:F,B5) -> 153000 | G5: =F5-H5 -> 0 | H5: =SUMIFS('All Transactions'!O:O,'All Transactions'!E:E,A5,'All Transactions'!F:F,B5) -> 153000 | I5: =IFERROR(H5/H$35,"") -> 0.17954754
A6: Building Materials | B6: Sand | C6: =SUMIFS('All Transactions'!I:I,'All Transactions'!E:E,A6,'All Transactions'!F:F,B6) -> 1838 | D6: CFT | E6: =IFERROR(F6/C6,"") -> 59.847661 | F6: =SUMIFS('All Transactions'!L:L,'All Transactions'!E:E,A6,'All Transactions'!F:F,B6) -> 110000 | G6: =F6-H6 -> 0 | H6: =SUMIFS('All Transactions'!O:O,'All Transactions'!E:E,A6,'All Transactions'!F:F,B6) -> 110000 | I6: =IFERROR(H6/H$35,"") -> 0.12908647
A7: Building Materials | B7: Concrete/Gitti | C7: =SUMIFS('All Transactions'!I:I,'All Transactions'!E:E,A7,'All Transactions'!F:F,B7) -> 65.14 | D7: Tonnes/Trailor | E7: =IFERROR(F7/C7,"") -> 2486.6749 | F7: =SUMIFS('All Transactions'!L:L,'All Transactions'!E:E,A7,'All Transactions'!F:F,B7) -> 161982 | G7: =F7-H7 -> 0 | H7: =SUMIFS('All Transactions'!O:O,'All Transactions'!E:E,A7,'All Transactions'!F:F,B7) -> 161982 | I7: =IFERROR(H7/H$35,"") -> 0.19008804
A8: Building Materials | B8: Cement-Ultratech Super | C8: =SUMIFS('All Transactions'!I:I,'All Transactions'!E:E,A8,'All Transactions'!F:F,B8) -> 200 | D8: Bags | E8: =IFERROR(F8/C8,"") -> 360 | F8: =SUMIFS('All Transactions'!L:L,'All Transactions'!E:E,A8,'All Transactions'!F:F,B8) -> 72000 | G8: =F8-H8 -> 0 | H8: =SUMIFS('All Transactions'!O:O,'All Transactions'!E:E,A8,'All Transactions'!F:F,B8) -> 72000 | I8: =IFERROR(H8/H$35,"") -> 0.08449296
A9: Building Materials | B9: Cement-Ultratech Normal | C9: =SUMIFS('All Transactions'!I:I,'All Transactions'!E:E,A9,'All Transactions'!F:F,B9) -> 0 | D9: Bags | E9: =IFERROR(F9/C9,"") | F9: =SUMIFS('All Transactions'!L:L,'All Transactions'!E:E,A9,'All Transactions'!F:F,B9) -> 0 | G9: =F9-H9 -> 0 | H9: =SUMIFS('All Transactions'!O:O,'All Transactions'!E:E,A9,'All Transactions'!F:F,B9) -> 0 | I9: =IFERROR(H9/H$35,"") -> 0
A10: Building Materials | B10: Cement-Ultratech Prem | C10: =SUMIFS('All Transactions'!I:I,'All Transactions'!E:E,A10,'All Transactions'!F:F,B10) -> 0 | D10: Bags | E10: =IFERROR(F10/C10,"") | F10: =SUMIFS('All Transactions'!L:L,'All Transactions'!E:E,A10,'All Transactions'!F:F,B10) -> 0 | G10: =F10-H10 -> 0 | H10: =SUMIFS('All Transactions'!O:O,'All Transactions'!E:E,A10,'All Transactions'!F:F,B10) -> 0 | I10: =IFERROR(H10/H$35,"") -> 0
A11: Building Materials | B11: Dr Fixit | C11: =SUMIFS('All Transactions'!I:I,'All Transactions'!E:E,A11,'All Transactions'!F:F,B11) -> 22 | D11: Litres | E11: =IFERROR(F11/C11,"") -> 245.45455 | F11: =SUMIFS('All Transactions'!L:L,'All Transactions'!E:E,A11,'All Transactions'!F:F,B11) -> 5400 | G11: =F11-H11 -> 0 | H11: =SUMIFS('All Transactions'!O:O,'All Transactions'!E:E,A11,'All Transactions'!F:F,B11) -> 5400 | I11: =IFERROR(H11/H$35,"") -> 0.006336972
A12: Building Materials | B12: Pipe PVC/GI | C12: =SUMIFS('All Transactions'!I:I,'All Transactions'!E:E,A12,'All Transactions'!F:F,B12) -> 0 | D12: Pcs | E12: =IFERROR(F12/C12,"") | F12: =SUMIFS('All Transactions'!L:L,'All Transactions'!E:E,A12,'All Transactions'!F:F,B12) -> 0 | G12: =F12-H12 -> 0 | H12: =SUMIFS('All Transactions'!O:O,'All Transactions'!E:E,A12,'All Transactions'!F:F,B12) -> 0 | I12: =IFERROR(H12/H$35,"") -> 0
A13: Building Materials | B13: Cover Block | C13: =SUMIFS('All Transactions'!I:I,'All Transactions'!E:E,A13,'All Transactions'!F:F,B13) -> 6 | D13: Packets | E13: =IFERROR(F13/C13,"") -> 350 | F13: =SUMIFS('All Transactions'!L:L,'All Transactions'!E:E,A13,'All Transactions'!F:F,B13) -> 2100 | G13: =F13-H13 -> 0 | H13: =SUMIFS('All Transactions'!O:O,'All Transactions'!E:E,A13,'All Transactions'!F:F,B13) -> 2100 | I13: =IFERROR(H13/H$35,"") -> 0.002464378
A14: Building Materials | B14: Kala Panni/Tar | C14: =SUMIFS('All Transactions'!I:I,'All Transactions'!E:E,A14,'All Transactions'!F:F,B14) -> 0 | D14: Kg | E14: =IFERROR(F14/C14,"") | F14: =SUMIFS('All Transactions'!L:L,'All Transactions'!E:E,A14,'All Transactions'!F:F,B14) -> 0 | G14: =F14-H14 -> 0 | H14: =SUMIFS('All Transactions'!O:O,'All Transactions'!E:E,A14,'All Transactions'!F:F,B14) -> 0 | I14: =IFERROR(H14/H$35,"") -> 0
A15: Building Materials | B15: Bamboo/Shuttering | C15: =SUMIFS('All Transactions'!I:I,'All Transactions'!E:E,A15,'All Transactions'!F:F,B15) -> 0 | D15: Nos | E15: =IFERROR(F15/C15,"") | F15: =SUMIFS('All Transactions'!L:L,'All Transactions'!E:E,A15,'All Transactions'!F:F,B15) -> 0 | G15: =F15-H15 -> 0 | H15: =SUMIFS('All Transactions'!O:O,'All Transactions'!E:E,A15,'All Transactions'!F:F,B15) -> 0 | I15: =IFERROR(H15/H$35,"") -> 0
A16: Building Materials | B16: Nails | C16: =SUMIFS('All Transactions'!I:I,'All Transactions'!E:E,A16,'All Transactions'!F:F,B16) -> 2 | D16: Kg/Bags | E16: =IFERROR(F16/C16,"") -> 800 | F16: =SUMIFS('All Transactions'!L:L,'All Transactions'!E:E,A16,'All Transactions'!F:F,B16) -> 1600 | G16: =F16-H16 -> 0 | H16: =SUMIFS('All Transactions'!O:O,'All Transactions'!E:E,A16,'All Transactions'!F:F,B16) -> 1600 | I16: =IFERROR(H16/H$35,"") -> 0.0018776213
... A34: Electrical | B34: Junction/Bend/Fitting | C34: =SUMIFS('All Transactions'!I:I,'All Transactions'!E:E,A34,'All Transactions'!F:F,B34) -> 0 | D34: Pcs | E34: =IFERROR(F34/C34,"") | F34: =SUMIFS('All Transactions'!L:L,'All Transactions'!E:E,A34,'All Transactions'!F:F,B34) -> 0 | G34: =F34-H34 -> 0 | H34: =SUMIFS('All Transactions'!O:O,'All Transactions'!E:E,A34,'All Transactions'!F:F,B34) -> 0 | I34: =IFERROR(H34/H$35,"") -> 0
A35: TOTAL MATERIALS | F35: =SUM(F5:F34) -> 865382 | G35: =SUM(G5:G34) -> 13240 | H35: =SUM(H5:H34) -> 852142

Sheet Labour Tracker
A1: ENGINEER & LABOUR PAYMENT TRACKER
A2: All payments to Engineer, Sonbhai, daily labour. Track by shift and purpose.
A4: Sr No | B4: Date | C4: Shift/Period | D4: Paid To | E4: Purpose | F4: Amount ₹ | G4: Payment Mode | H4: Paid By | I4: Running Total ₹ | J4: Remarks
A5: 1 | B5: 46149 | C5: One-time | D5: Econ Builder | E5: Visit Charge | F5: 5000 | G5: GPay | H5: Papa | I5: =IF(F5="","",F5) -> 5000 | J5: Advance for new house construction
A6: 2 | B6: 46149 | C6: Daily | D6: Daily Labour | E6: Labour Wages | F6: 1500 | G6: GPay | H6: Self-GPay | I6: =IF(F6="","",IF(I5="",F6,I5+F6)) -> 6500 | J6: Chanarveer - site cleaning
A7: 3 | I7: =IF(F7="","",IF(I6="",F7,I6+F7))
A8: 4 | I8: =IF(F8="","",IF(I7="",F8,I7+F8))
A9: 5 | I9: =IF(F9="","",IF(I8="",F9,I8+F9))
A10: 6 | I10: =IF(F10="","",IF(I9="",F10,I9+F10))
A11: 7 | I11: =IF(F11="","",IF(I10="",F11,I10+F11))
A12: 8 | I12: =IF(F12="","",IF(I11="",F12,I11+F12))
A13: 9 | I13: =IF(F13="","",IF(I12="",F13,I12+F13))
A14: 10 | I14: =IF(F14="","",IF(I13="",F14,I13+F14))
A15: 11 | I15: =IF(F15="","",IF(I14="",F15,I14+F15))
A16: 12 | I16: =IF(F16="","",IF(I15="",F16,I15+F16))
A17: 13 | I17: =IF(F17="","",IF(I16="",F17,I16+F17))
A18: 14 | I18: =IF(F18="","",IF(I17="",F18,I17+F18))
... A504: 500 | I504: =IF(F504="","",IF(I503="",F504,I503+F504))

Sheet Monthly Summary
A1: MONTH-WISE EXPENSE SUMMARY
A2: Auto-calculated from All Transactions using SUMIFS by month and category.
A4: Month | B4: Building Materials ₹ | C4: Steel/Iron ₹ | D4: Electrical ₹ | E4: Labour ₹ | F4: Transport ₹ | G4: Food/Provisions ₹ | H4: Professional Fees ₹ | I4: Land Development ₹ | J4: Miscellaneous ₹ | K4: TOTAL ₹
A5: May-2026 | B5: =SUMIFS('All Transactions'!O:O,'All Transactions'!C:C,A5,'All Transactions'!E:E,"Building Materials") -> 489182 | C5: =SUMIFS('All Transactions'!O:O,'All Transactions'!C:C,A5,'All Transactions'!E:E,"Steel/Iron") -> 161100 | D5: =SUMIFS('All Transactions'!O:O,'All Transactions'!C:C,A5,'All Transactions'!E:E,"Electrical") -> 0 | E5: =SUMIFS('All Transactions'!O:O,'All Transactions'!C:C,A5,'All Transactions'!E:E,"Labour") -> 2650 | F5: =SUMIFS('All Transactions'!O:O,'All Transactions'!C:C,A5,'All Transactions'!E:E,"Transport") -> 800 | G5: =SUMIFS('All Transactions'!O:O,'All Transactions'!C:C,A5,'All Transactions'!E:E,"Food/Provisions") -> 3285 | H5: =SUMIFS('All Transactions'!O:O,'All Transactions'!C:C,A5,'All Transactions'!E:E,"Professional Fees") -> 126000 | I5: =SUMIFS('All Transactions'!O:O,'All Transactions'!C:C,A5,'All Transactions'!E:E,"Land Development") -> 42100 | J5: =SUMIFS('All Transactions'!O:O,'All Transactions'!C:C,A5,'All Transactions'!E:E,"Miscellaneous") -> 4475 | K5: =SUM(B5:J5) -> 829592
A6: Jun-2026 | B6: =SUMIFS('All Transactions'!O:O,'All Transactions'!C:C,A6,'All Transactions'!E:E,"Building Materials") -> 20600 | C6: =SUMIFS('All Transactions'!O:O,'All Transactions'!C:C,A6,'All Transactions'!E:E,"Steel/Iron") -> 181260 | D6: =SUMIFS('All Transactions'!O:O,'All Transactions'!C:C,A6,'All Transactions'!E:E,"Electrical") -> 0 | E6: =SUMIFS('All Transactions'!O:O,'All Transactions'!C:C,A6,'All Transactions'!E:E,"Labour") -> 23570 | F6: =SUMIFS('All Transactions'!O:O,'All Transactions'!C:C,A6,'All Transactions'!E:E,"Transport") -> 500 | G6: =SUMIFS('All Transactions'!O:O,'All Transactions'!C:C,A6,'All Transactions'!E:E,"Food/Provisions") -> 0 | H6: =SUMIFS('All Transactions'!O:O,'All Transactions'!C:C,A6,'All Transactions'!E:E,"Professional Fees") -> 100000 | I6: =SUMIFS('All Transactions'!O:O,'All Transactions'!C:C,A6,'All Transactions'!E:E,"Land Development") -> 0 | J6: =SUMIFS('All Transactions'!O:O,'All Transactions'!C:C,A6,'All Transactions'!E:E,"Miscellaneous") -> 0 | K6: =SUM(B6:J6) -> 325930
A7: Jul-2026 | B7: =SUMIFS('All Transactions'!O:O,'All Transactions'!C:C,A7,'All Transactions'!E:E,"Building Materials") -> 0 | C7: =SUMIFS('All Transactions'!O:O,'All Transactions'!C:C,A7,'All Transactions'!E:E,"Steel/Iron") -> 0 | D7: =SUMIFS('All Transactions'!O:O,'All Transactions'!C:C,A7,'All Transactions'!E:E,"Electrical") -> 0 | E7: =SUMIFS('All Transactions'!O:O,'All Transactions'!C:C,A7,'All Transactions'!E:E,"Labour") -> 0 | F7: =SUMIFS('All Transactions'!O:O,'All Transactions'!C:C,A7,'All Transactions'!E:E,"Transport") -> 0 | G7: =SUMIFS('All Transactions'!O:O,'All Transactions'!C:C,A7,'All Transactions'!E:E,"Food/Provisions") -> 0 | H7: =SUMIFS('All Transactions'!O:O,'All Transactions'!C:C,A7,'All Transactions'!E:E,"Professional Fees") -> 0 | I7: =SUMIFS('All Transactions'!O:O,'All Transactions'!C:C,A7,'All Transactions'!E:E,"Land Development") -> 0 | J7: =SUMIFS('All Transactions'!O:O,'All Transactions'!C:C,A7,'All Transactions'!E:E,"Miscellaneous") -> 0 | K7: =SUM(B7:J7) -> 0
