Workbook

Sheet 📖 How to Use
A1: 📖 How to Use This Tracker
A2: Bihar Home Construction — Project Home Tracker
B4: 🏗️ OVERVIEW
B5: This workbook tracks ALL expenses for your home construction in Bihar.
B6: It has 9 sheets. You mainly enter data in 2 sheets and the rest auto-calculate.
B8: 👉 YOU ENTER DATA IN:
B9: 1. "All Transactions" — Every material/service received
B10: 2. "Payment Tracker" — Every payment you make
B12: 👉 THESE AUTO-CALCULATE (don't edit formulas):
B13: 3. Material Summary — Total by material type
B14: 4. Monthly Summary — Spend by month
B15: 5. Vendor Summary — Billed vs Paid per vendor
B16: 6. Dashboard — KPI overview
B18: 👉 OPTIONAL SHEETS:
... B23: 📝 SHEET: "All Transactions" — YOUR MAIN ENTRY SHEET
B24: What to enter: | C24: One row for every material/item/service received.
B25: When to enter: | C25: Same day the material arrives or service is done.
B27: COLUMNS:
B28: Column A — Sr | C28: Auto-increment serial number (1, 2, 3...)
B29: Column B — Date | C29: Date of delivery/service (DD-MM-YYYY format)
B30: Column C — Month | C30: Text like "May-2026", "Jun-2026" (for SUMIFS)
B31: Column D — Phase | C31: Foundation / Plinth / Superstructure / Finishing
B32: Column E — Category | C32: Building Materials / Steel/Iron / Professional Fees / Land Development / Labour / Transport / etc.
B33: Column F — Subcategory | C33: Bricks / Cement-Ultratech Super / Tiscon-12mm / JCB / Earth Filling Labour / etc.
B34: Column G — Item Description | C34: Detailed description: "Tiscon 12mm TMT - 100 PC @ ₹908 (Bill 2)"
B35: Column H — Vendor | C35: Pappu Hardware / Brick Company / Econ Builder / etc.
B36: Column I — Qty | C36: Quantity (100, 50, 27.5, 17.5 etc.)
B37: Column J — Unit | C37: Pcs / Bags / Ton / CFT / Nos / Hrs / Lumpsum / L / Kg
B38: Column K — Rate | C38: Price per unit (₹908, ₹360, ₹8.5 etc.)
B39: Column L — Gross Amount | C39: Qty × Rate (enter manually: 100 × 908 = 90800)
... B44: Column Q — Payment Mode | C44: "GPay" / "Bank Transfer" / "Cash"
B46: 💡 TIP: Copy formulas from the row above when adding new rows (Col N and O).
B48: 💳 SHEET: "Payment Tracker" — CASH FLOW LOG
B49: What to enter: | C49: One row for every payment made (GPay, Bank, Cash).
B50: When to enter: | C50: Same day the payment is made.
B51: Why separate from Transactions? | C51: Because payments don't always match deliveries:
C52: • Advance payments (Brick Company ₹3.69L before delivery)
C53: • Part payments (Pappu Hardware Bill 63 paid in 2 parts)
C54: • One payment for multiple items (Bill 2 covers 8 items)
B56: COLUMNS:
...

Sheet Dashboard
A2: 🏠 BIHAR HOME BUILD — PROJECT DASHBOARD
A3: Plinth Phase · Started 7 May 2026 | G3: Auto-updates from All Transactions & Payment Tracker
B6: TOTAL CASH PAID | E6: MATERIAL ON SITE | H6: VENDOR ADVANCE | K6: BALANCE DUE
B7: =SUM('Payment Tracker'!G5:G500) | E7: ='Material Summary'!H35 | H7: =-SUMIF('Vendor Summary'!E5:E16,"<0") | K7: =SUMIF('Vendor Summary'!E5:E16,">0")
B8: All payments made to date | E8: Net billed value of materials | H8: Advance paid beyond billed (all vendors) | K8: Unpaid vendor bills
B10: 👥 WHO PAID | E10: 📊 CATEGORY BREAKDOWN | H10: 🏪 VENDOR STATUS
B11: Payer | C11: Amount ₹ | E11: Category | F11: Amount ₹ | H11: Vendor | I11: Billed ₹ | J11: Paid ₹ | K11: Pending ₹ | L11: Status
B12: Avinash | C12: =SUMIF('Payment Tracker'!C:C,"Self",'Payment Tracker'!G:G)+SUMIF('Payment Tracker'!C:C,"Self-GPay",'Payment Tracker'!G:G)+SUMIF('Payment Tracker'!C:C,"Self-Bank Transfer",'Payment Tracker'!G:G) | E12: Building Materials | F12: =SUMIFS('All Transactions'!O:O,'All Transactions'!E:E,E12) | H12: Pappu Hardware | I12: =SUMIF('All Transactions'!H:H,H12,'All Transactions'!O:O) | J12: =SUMIF('Payment Tracker'!D:D,H12,'Payment Tracker'!G:G) | K12: =IF(I12=0,"—",I12-J12) | L12: =IF(I12=0,"—",IF(K12>0,"⚠ DUE",IF(K12<0,"🔵 ADV","✅ PAID")))
B13: Papa | C13: =SUMIF('Payment Tracker'!C:C,B13,'Payment Tracker'!G:G) | E13: Steel / Iron | F13: =SUMIFS('All Transactions'!O:O,'All Transactions'!E:E,E13) | H13: Econ Builder | I13: =SUMIF('All Transactions'!H:H,H13,'All Transactions'!O:O) | J13: =SUMIF('Payment Tracker'!D:D,H13,'Payment Tracker'!G:G) | K13: =IF(I13=0,"—",I13-J13) | L13: =IF(I13=0,"—",IF(K13>0,"⚠ DUE",IF(K13<0,"🔵 ADV","✅ PAID")))
B14: Chota Bhai | C14: =SUMIF('Payment Tracker'!C:C,B14,'Payment Tracker'!G:G) | E14: Electrical | F14: =SUMIFS('All Transactions'!O:O,'All Transactions'!E:E,E14) | H14: Brick Company | I14: =SUMIF('All Transactions'!H:H,H14,'All Transactions'!O:O) | J14: =SUMIF('Payment Tracker'!D:D,H14,'Payment Tracker'!G:G) | K14: =IF(I14=0,"—",I14-J14) | L14: =IF(I14=0,"—",IF(K14>0,"⚠ DUE",IF(K14<0,"🔵 ADV","✅ PAID")))
E15: Labour | F15: =SUMIFS('All Transactions'!O:O,'All Transactions'!E:E,E15) | H15: Concrete Supplier | I15: =SUMIF('All Transactions'!H:H,H15,'All Transactions'!O:O) | J15: =SUMIF('Payment Tracker'!D:D,H15,'Payment Tracker'!G:G) | K15: =IF(I15=0,"—",I15-J15) | L15: =IF(I15=0,"—",IF(K15>0,"⚠ DUE",IF(K15<0,"🔵 ADV","✅ PAID")))
E16: Professional Fees | F16: =SUMIFS('All Transactions'!O:O,'All Transactions'!E:E,E16) | H16: Sand Truck Wala | I16: =SUMIF('All Transactions'!H:H,H16,'All Transactions'!O:O) | J16: =SUMIF('Payment Tracker'!D:D,H16,'Payment Tracker'!G:G) | K16: =IF(I16=0,"—",I16-J16) | L16: =IF(I16=0,"—",IF(K16>0,"⚠ DUE",IF(K16<0,"🔵 ADV","✅ PAID")))
B17: TOTAL | C17: =SUM(C12:C16) | E17: Land Development | F17: =SUMIFS('All Transactions'!O:O,'All Transactions'!E:E,E17) | H17: Mukesh Yadav | I17: =SUMIF('All Transactions'!H:H,H17,'All Transactions'!O:O) | J17: =SUMIF('Payment Tracker'!D:D,H17,'Payment Tracker'!G:G) | K17: =IF(I17=0,"—",I17-J17) | L17: =IF(I17=0,"—",IF(K17>0,"⚠ DUE",IF(K17<0,"🔵 ADV","✅ PAID")))
E18: Transport · Food · Misc | F18: =SUMIFS('All Transactions'!O:O,'All Transactions'!E:E,E18) | H18: Daily Labour | I18: =SUMIF('All Transactions'!H:H,H18,'All Transactions'!O:O) | J18: =SUMIF('Payment Tracker'!D:D,H18,'Payment Tracker'!G:G) | K18: =IF(I18=0,"—",I18-J18) | L18: =IF(I18=0,"—",IF(K18>0,"⚠ DUE",IF(K18<0,"🔵 ADV","✅ PAID")))
H19: Khutauna Chirai mill | I19: =SUMIF('All Transactions'!H:H,H19,'All Transactions'!O:O) | J19: =SUMIF('Payment Tracker'!D:D,H19,'Payment Tracker'!G:G) | K19: =IF(I19=0,"—",I19-J19) | L19: =IF(I19=0,"—",IF(K19>0,"⚠ DUE",IF(K19<0,"🔵 ADV","✅ PAID")))
E20: TOTAL | F20: =SUM(F12:F19) | H20: Local Purchase | I20: =SUMIF('All Transactions'!H:H,H20,'All Transactions'!O:O) | J20: =SUMIF('Payment Tracker'!D:D,H20,'Payment Tracker'!G:G) | K20: =IF(I20=0,"—",I20-J20) | L20: =IF(I20=0,"—",IF(K20>0,"⚠ DUE",IF(K20<0,"🔵 ADV","✅ PAID")))
H21: Other vendors | I21: ='Vendor Summary'!C17-SUM(I12:I20) | J21: ='Vendor Summary'!D17-SUM(J12:J20) | K21: =IF(I21=0,"—",I21-J21) | L21: =IF(I21=0,"—",IF(K21>0,"⚠ DUE",IF(K21<0,"🔵 ADV","✅ PAID")))
H22: TOTAL | I22: =SUM(I12:I21) | J22: =SUM(J12:J21) | K22: =SUM(K12:K21)
B24: 📦 MATERIALS ON SITE | K24: 📅 MONTHLY TREND
B25: Material | C25: Qty | D25: Unit | E25: Avg Rate | F25: Gross ₹ | G25: Disc ₹ | H25: Net ₹ | I25: % Share | K25: Month | L25: Spend ₹
B26: =IF('Material Summary'!B5<>"",'Material Summary'!B5,"") | C26: =IF('Material Summary'!C5<>"",'Material Summary'!C5,"") | D26: =IF('Material Summary'!D5<>"",'Material Summary'!D5,"") | E26: =IF('Material Summary'!E5<>"",'Material Summary'!E5,"") | F26: =IF('Material Summary'!F5<>"",'Material Summary'!F5,"") | G26: =IF('Material Summary'!G5<>"",'Material Summary'!G5,"") | H26: =IF('Material Summary'!H5<>"",'Material Summary'!H5,"") | I26: =IF('Material Summary'!I5<>"",'Material Summary'!I5,"") | K26: May-2026 | L26: =SUMIFS('All Transactions'!O:O,'All Transactions'!C:C,K26)
B27: =IF('Material Summary'!B6<>"",'Material Summary'!B6,"") | C27: =IF('Material Summary'!C6<>"",'Material Summary'!C6,"") | D27: =IF('Material Summary'!D6<>"",'Material Summary'!D6,"") | E27: =IF('Material Summary'!E6<>"",'Material Summary'!E6,"") | F27: =IF('Material Summary'!F6<>"",'Material Summary'!F6,"") | G27: =IF('Material Summary'!G6<>"",'Material Summary'!G6,"") | H27: =IF('Material Summary'!H6<>"",'Material Summary'!H6,"") | I27: =IF('Material Summary'!I6<>"",'Material Summary'!I6,"") | K27: Jun-2026 | L27: =SUMIFS('All Transactions'!O:O,'All Transactions'!C:C,K27)
B28: =IF('Material Summary'!B7<>"",'Material Summary'!B7,"") | C28: =IF('Material Summary'!C7<>"",'Material Summary'!C7,"") | D28: =IF('Material Summary'!D7<>"",'Material Summary'!D7,"") | E28: =IF('Material Summary'!E7<>"",'Material Summary'!E7,"") | F28: =IF('Material Summary'!F7<>"",'Material Summary'!F7,"") | G28: =IF('Material Summary'!G7<>"",'Material Summary'!G7,"") | H28: =IF('Material Summary'!H7<>"",'Material Summary'!H7,"") | I28: =IF('Material Summary'!I7<>"",'Material Summary'!I7,"") | K28: Jul-2026 | L28: =SUMIFS('All Transactions'!O:O,'All Transactions'!C:C,K28)
B29: =IF('Material Summary'!B8<>"",'Material Summary'!B8,"") | C29: =IF('Material Summary'!C8<>"",'Material Summary'!C8,"") | D29: =IF('Material Summary'!D8<>"",'Material Summary'!D8,"") | E29: =IF('Material Summary'!E8<>"",'Material Summary'!E8,"") | F29: =IF('Material Summary'!F8<>"",'Material Summary'!F8,"") | G29: =IF('Material Summary'!G8<>"",'Material Summary'!G8,"") | H29: =IF('Material Summary'!H8<>"",'Material Summary'!H8,"") | I29: =IF('Material Summary'!I8<>"",'Material Summary'!I8,"") | K29: Aug-2026 | L29: =SUMIFS('All Transactions'!O:O,'All Transactions'!C:C,K29)
B30: =IF('Material Summary'!B9<>"",'Material Summary'!B9,"") | C30: =IF('Material Summary'!C9<>"",'Material Summary'!C9,"") | D30: =IF('Material Summary'!D9<>"",'Material Summary'!D9,"") | E30: =IF('Material Summary'!E9<>"",'Material Summary'!E9,"") | F30: =IF('Material Summary'!F9<>"",'Material Summary'!F9,"") | G30: =IF('Material Summary'!G9<>"",'Material Summary'!G9,"") | H30: =IF('Material Summary'!H9<>"",'Material Summary'!H9,"") | I30: =IF('Material Summary'!I9<>"",'Material Summary'!I9,"") | K30: Sep-2026 | L30: =SUMIFS('All Transactions'!O:O,'All Transactions'!C:C,K30)
B31: =IF('Material Summary'!B10<>"",'Material Summary'!B10,"") | C31: =IF('Material Summary'!C10<>"",'Material Summary'!C10,"") | D31: =IF('Material Summary'!D10<>"",'Material Summary'!D10,"") | E31: =IF('Material Summary'!E10<>"",'Material Summary'!E10,"") | F31: =IF('Material Summary'!F10<>"",'Material Summary'!F10,"") | G31: =IF('Material Summary'!G10<>"",'Material Summary'!G10,"") | H31: =IF('Material Summary'!H10<>"",'Material Summary'!H10,"") | I31: =IF('Material Summary'!I10<>"",'Material Summary'!I10,"") | K31: Oct-2026 | L31: =SUMIFS('All Transactions'!O:O,'All Transactions'!C:C,K31)
B32: =IF('Material Summary'!B11<>"",'Material Summary'!B11,"") | C32: =IF('Material Summary'!C11<>"",'Material Summary'!C11,"") | D32: =IF('Material Summary'!D11<>"",'Material Summary'!D11,"") | E32: =IF('Material Summary'!E11<>"",'Material Summary'!E11,"") | F32: =IF('Material Summary'!F11<>"",'Material Summary'!F11,"") | G32: =IF('Material Summary'!G11<>"",'Material Summary'!G11,"") | H32: =IF('Material Summary'!H11<>"",'Material Summary'!H11,"") | I32: =IF('Material Summary'!I11<>"",'Material Summary'!I11,"") | K32: Nov-2026 | L32: =SUMIFS('All Transactions'!O:O,'All Transactions'!C:C,K32)
B33: =IF('Material Summary'!B12<>"",'Material Summary'!B12,"") | C33: =IF('Material Summary'!C12<>"",'Material Summary'!C12,"") | D33: =IF('Material Summary'!D12<>"",'Material Summary'!D12,"") | E33: =IF('Material Summary'!E12<>"",'Material Summary'!E12,"") | F33: =IF('Material Summary'!F12<>"",'Material Summary'!F12,"") | G33: =IF('Material Summary'!G12<>"",'Material Summary'!G12,"") | H33: =IF('Material Summary'!H12<>"",'Material Summary'!H12,"") | I33: =IF('Material Summary'!I12<>"",'Material Summary'!I12,"") | K33: Dec-2026 | L33: =SUMIFS('All Transactions'!O:O,'All Transactions'!C:C,K33)
B34: =IF('Material Summary'!B13<>"",'Material Summary'!B13,"") | C34: =IF('Material Summary'!C13<>"",'Material Summary'!C13,"") | D34: =IF('Material Summary'!D13<>"",'Material Summary'!D13,"") | E34: =IF('Material Summary'!E13<>"",'Material Summary'!E13,"") | F34: =IF('Material Summary'!F13<>"",'Material Summary'!F13,"") | G34: =IF('Material Summary'!G13<>"",'Material Summary'!G13,"") | H34: =IF('Material Summary'!H13<>"",'Material Summary'!H13,"") | I34: =IF('Material Summary'!I13<>"",'Material Summary'!I13,"") | K34: Jan-2027 | L34: =SUMIFS('All Transactions'!O:O,'All Transactions'!C:C,K34)
B35: =IF('Material Summary'!B14<>"",'Material Summary'!B14,"") | C35: =IF('Material Summary'!C14<>"",'Material Summary'!C14,"") | D35: =IF('Material Summary'!D14<>"",'Material Summary'!D14,"") | E35: =IF('Material Summary'!E14<>"",'Material Summary'!E14,"") | F35: =IF('Material Summary'!F14<>"",'Material Summary'!F14,"") | G35: =IF('Material Summary'!G14<>"",'Material Summary'!G14,"") | H35: =IF('Material Summary'!H14<>"",'Material Summary'!H14,"") | I35: =IF('Material Summary'!I14<>"",'Material Summary'!I14,"") | K35: Feb-2027 | L35: =SUMIFS('All Transactions'!O:O,'All Transactions'!C:C,K35)
B36: =IF('Material Summary'!B15<>"",'Material Summary'!B15,"") | C36: =IF('Material Summary'!C15<>"",'Material Summary'!C15,"") | D36: =IF('Material Summary'!D15<>"",'Material Summary'!D15,"") | E36: =IF('Material Summary'!E15<>"",'Material Summary'!E15,"") | F36: =IF('Material Summary'!F15<>"",'Material Summary'!F15,"") | G36: =IF('Material Summary'!G15<>"",'Material Summary'!G15,"") | H36: =IF('Material Summary'!H15<>"",'Material Summary'!H15,"") | I36: =IF('Material Summary'!I15<>"",'Material Summary'!I15,"") | K36: Mar-2027 | L36: =SUMIFS('All Transactions'!O:O,'All Transactions'!C:C,K36)
B37: =IF('Material Summary'!B16<>"",'Material Summary'!B16,"") | C37: =IF('Material Summary'!C16<>"",'Material Summary'!C16,"") | D37: =IF('Material Summary'!D16<>"",'Material Summary'!D16,"") | E37: =IF('Material Summary'!E16<>"",'Material Summary'!E16,"") | F37: =IF('Material Summary'!F16<>"",'Material Summary'!F16,"") | G37: =IF('Material Summary'!G16<>"",'Material Summary'!G16,"") | H37: =IF('Material Summary'!H16<>"",'Material Summary'!H16,"") | I37: =IF('Material Summary'!I16<>"",'Material Summary'!I16,"") | K37: Apr-2027 | L37: =SUMIFS('All Transactions'!O:O,'All Transactions'!C:C,K37)
B38: =IF('Material Summary'!B17<>"",'Material Summary'!B17,"") | C38: =IF('Material Summary'!C17<>"",'Material Summary'!C17,"") | D38: =IF('Material Summary'!D17<>"",'Material Summary'!D17,"") | E38: =IF('Material Summary'!E17<>"",'Material Summary'!E17,"") | F38: =IF('Material Summary'!F17<>"",'Material Summary'!F17,"") | G38: =IF('Material Summary'!G17<>"",'Material Summary'!G17,"") | H38: =IF('Material Summary'!H17<>"",'Material Summary'!H17,"") | I38: =IF('Material Summary'!I17<>"",'Material Summary'!I17,"")
B39: =IF('Material Summary'!B18<>"",'Material Summary'!B18,"") | C39: =IF('Material Summary'!C18<>"",'Material Summary'!C18,"") | D39: =IF('Material Summary'!D18<>"",'Material Summary'!D18,"") | E39: =IF('Material Summary'!E18<>"",'Material Summary'!E18,"") | F39: =IF('Material Summary'!F18<>"",'Material Summary'!F18,"") | G39: =IF('Material Summary'!G18<>"",'Material Summary'!G18,"") | H39: =IF('Material Summary'!H18<>"",'Material Summary'!H18,"") | I39: =IF('Material Summary'!I18<>"",'Material Summary'!I18,"")
B40: =IF('Material Summary'!B19<>"",'Material Summary'!B19,"") | C40: =IF('Material Summary'!C19<>"",'Material Summary'!C19,"") | D40: =IF('Material Summary'!D19<>"",'Material Summary'!D19,"") | E40: =IF('Material Summary'!E19<>"",'Material Summary'!E19,"") | F40: =IF('Material Summary'!F19<>"",'Material Summary'!F19,"") | G40: =IF('Material Summary'!G19<>"",'Material Summary'!G19,"") | H40: =IF('Material Summary'!H19<>"",'Material Summary'!H19,"") | I40: =IF('Material Summary'!I19<>"",'Material Summary'!I19,"")
B41: =IF('Material Summary'!B20<>"",'Material Summary'!B20,"") | C41: =IF('Material Summary'!C20<>"",'Material Summary'!C20,"") | D41: =IF('Material Summary'!D20<>"",'Material Summary'!D20,"") | E41: =IF('Material Summary'!E20<>"",'Material Summary'!E20,"") | F41: =IF('Material Summary'!F20<>"",'Material Summary'!F20,"") | G41: =IF('Material Summary'!G20<>"",'Material Summary'!G20,"") | H41: =IF('Material Summary'!H20<>"",'Material Summary'!H20,"") | I41: =IF('Material Summary'!I20<>"",'Material Summary'!I20,"")
B42: =IF('Material Summary'!B21<>"",'Material Summary'!B21,"") | C42: =IF('Material Summary'!C21<>"",'Material Summary'!C21,"") | D42: =IF('Material Summary'!D21<>"",'Material Summary'!D21,"") | E42: =IF('Material Summary'!E21<>"",'Material Summary'!E21,"") | F42: =IF('Material Summary'!F21<>"",'Material Summary'!F21,"") | G42: =IF('Material Summary'!G21<>"",'Material Summary'!G21,"") | H42: =IF('Material Summary'!H21<>"",'Material Summary'!H21,"") | I42: =IF('Material Summary'!I21<>"",'Material Summary'!I21,"")
B43: =IF('Material Summary'!B22<>"",'Material Summary'!B22,"") | C43: =IF('Material Summary'!C22<>"",'Material Summary'!C22,"") | D43: =IF('Material Summary'!D22<>"",'Material Summary'!D22,"") | E43: =IF('Material Summary'!E22<>"",'Material Summary'!E22,"") | F43: =IF('Material Summary'!F22<>"",'Material Summary'!F22,"") | G43: =IF('Material Summary'!G22<>"",'Material Summary'!G22,"") | H43: =IF('Material Summary'!H22<>"",'Material Summary'!H22,"") | I43: =IF('Material Summary'!I22<>"",'Material Summary'!I22,"")
B44: =IF('Material Summary'!B23<>"",'Material Summary'!B23,"") | C44: =IF('Material Summary'!C23<>"",'Material Summary'!C23,"") | D44: =IF('Material Summary'!D23<>"",'Material Summary'!D23,"") | E44: =IF('Material Summary'!E23<>"",'Material Summary'!E23,"") | F44: =IF('Material Summary'!F23<>"",'Material Summary'!F23,"") | G44: =IF('Material Summary'!G23<>"",'Material Summary'!G23,"") | H44: =IF('Material Summary'!H23<>"",'Material Summary'!H23,"") | I44: =IF('Material Summary'!I23<>"",'Material Summary'!I23,"")
B45: =IF('Material Summary'!B24<>"",'Material Summary'!B24,"") | C45: =IF('Material Summary'!C24<>"",'Material Summary'!C24,"") | D45: =IF('Material Summary'!D24<>"",'Material Summary'!D24,"") | E45: =IF('Material Summary'!E24<>"",'Material Summary'!E24,"") | F45: =IF('Material Summary'!F24<>"",'Material Summary'!F24,"") | G45: =IF('Material Summary'!G24<>"",'Material Summary'!G24,"") | H45: =IF('Material Summary'!H24<>"",'Material Summary'!H24,"") | I45: =IF('Material Summary'!I24<>"",'Material Summary'!I24,"")

Sheet Master Data
A1: MASTER DATA — Categories, Vendors & Reference Lists
A2: Add new categories/vendors here. All dropdowns across sheets pull from these lists.
A4: CATEGORY | B4: SUB-CATEGORY | C4: UNIT | E4: VENDOR NAME | F4: VENDOR TYPE | G4: DEFAULT PAY MODE | I4: PAID BY | J4: PAYMENT MODE | K4: CONSTRUCTION PHASE | M4: SubCatList | N4: UnitList
A5: Building Materials | B5: Bricks | C5: Nos/Trailor | E5: Pappu Hardware | F5: Hardware/Steel | G5: GPay | I5: Self-GPay | J5: GPay | K5: Land Development | M5: Auto/Taxi | N5: Bags
A6: Building Materials | B6: Sand | C6: CFT | E6: Brick Company | F6: Bricks | G6: GPay | I6: Self-Paytm | J6: Paytm | K6: Foundation | M6: Bamboo/Shuttering | N6: Bundle/Metres
A7: Building Materials | B7: Concrete/Gitti | C7: Tonnes/Trailor | E7: Sand Truck Wala | F7: Sand | G7: GPay | I7: Self-Cash | J7: Cash | K7: Plinth | M7: Binding Wire | N7: CFT
A8: Building Materials | B8: Cement-Ultratech Super | C8: Bags | E8: Concrete Supplier | F8: Concrete/Gitti | G8: GPay/Paytm | I8: Self-Bank Transfer | J8: Bank Transfer | K8: Superstructure | M8: Blade | N8: Days
A9: Building Materials | B9: Cement-Ultratech Normal | C9: Bags | E9: Dinesh-Electrician | F9: Electrical Items | G9: GPay | I9: Through Sonbhai | J9: UPI | K9: Roof/Dhalai | M9: Boards/Plates | N9: Days/Lumpsum
A10: Building Materials | B10: Cement-Ultratech Prem | C10: Bags | E10: Mukesh Yadav | F10: Mitti Bharai/JCB | G10: GPay | I10: Through Engineer | J10: Cheque | K10: Electrical | M10: Bricks | N10: Kg
A11: Building Materials | B11: Dr Fixit | C11: Litres | E11: Chand Ansari | F11: Dhalai Machine | G11: GPay | I11: Through Ajay | K11: Plumbing | M11: Cement-Ultratech Normal | N11: Kg/Bags
A12: Building Materials | B12: Pipe PVC/GI | C12: Pcs | E12: Ajay Mahto | F12: Labour/Transport | G12: GPay | I12: Papa | K12: Plastering | M12: Cement-Ultratech Prem | N12: Litres
A13: Building Materials | B13: Cover Block | C13: Packets | E13: Mukhiya | F13: Bamboo/Misc | G13: Cash | I13: Chota Bhai | K13: Flooring | M13: Cement-Ultratech Super | N13: Lumpsum
A14: Building Materials | B14: Kala Panni/Tar | C14: Kg | E14: Sonbhai-Coordinator | F14: Labour Payments/Misc | G14: GPay | K14: Painting | M14: Concrete/Gitti | N14: Nos
A15: Building Materials | B15: Bamboo/Shuttering | C15: Nos | E15: Econ Builder | F15: Engineering/Labour | G15: GPay | K15: Finishing | M15: Conduit Pipe | N15: Nos/Trailor
A16: Building Materials | B16: Nails | C16: Kg/Bags | E16: Rinku Devi A/c | F16: Labour Account | G16: GPay | K16: Boundary Wall | M16: Cover Block | N16: Packets
A17: Building Materials | B17: Binding Wire | C17: Kg | E17: Naveen Hardware | F17: Cement/Building Materials | G17: Bank Transfer | M17: Daily Labour-Mitti Bharai | N17: Pcs
A18: Building Materials | B18: Blade | C18: Pcs | E18: Daily Labour | M18: Dhalai Machine Rent | N18: Tonnes/Trailor
A19: Steel/Iron | B19: Tiscon 16mm | C19: Pcs | E19: Khutauna Chirai mill | M19: Dr Fixit | N19: Trips
A20: Steel/Iron | B20: Tiscon 12mm | C20: Pcs | E20: Local Purchase | M20: Engineer Labour Charge | N20: Visit
A21: Steel/Iron | B21: Tiscon 10mm | C21: Pcs | E21: Mittal Electric | M21: Engineer Visit Charge
A22: Steel/Iron | B22: Tiscon 8mm | C22: Pcs | M22: Fan Hooks/Holders
A23: Steel/Iron | B23: Tiscon 6mm | C23: Pcs | M23: Junction/Bend/Fitting
A24: Electrical | B24: Wire 4mm | C24: Bundle/Metres | M24: Kala Panni/Tar
A25: Electrical | B25: Wire 2.5mm | C25: Bundle/Metres | M25: Labour Food-Rice/Wheat/Gas
A26: Electrical | B26: Wire 1.5mm | C26: Bundle/Metres | M26: Ladies Labour-Bricks
A27: Electrical | B27: Wire 1mm | C27: Bundle/Metres | M27: Land Levelling/Filling
A28: Electrical | B28: Wire 0.75mm | C28: Bundle/Metres | M28: MCB/Distribution Board
A29: Electrical | B29: Switches/Sockets | C29: Pcs | M29: Map/Drawing Charge
A30: Electrical | B30: MCB/Distribution Board | C30: Pcs | M30: Nails
A31: Electrical | B31: Conduit Pipe | C31: Pcs | M31: Pipe PVC/GI
A32: Electrical | B32: Fan Hooks/Holders | C32: Pcs | M32: Sand
A33: Electrical | B33: Boards/Plates | C33: Pcs | M33: Skilled Labour
... A48: Miscellaneous | B48: Tools/Consumables | C48: Lumpsum | M48: Wire 4mm

Sheet All Transactions
A1: HOME CONSTRUCTION — EXPENSE REGISTER
A2: Enter every payment/expense as one row. Blue cells = input. Black cells = auto-calculated formulas.
A4: Sr No | B4: Date | C4: Month | D4: Construction Phase | E4: Category | F4: Sub-Category | G4: Item Description | H4: Vendor/Paid To | I4: Qty | J4: Unit | K4: Rate ₹ | L4: Gross Amt ₹ | M4: Discount % | N4: Discount amount | O4: Net Amt ₹ | P4: Paid By | Q4: Payment Mode | R4: Building Unit (B/C, blank=joint 50/50)
A5: 2 | B5: 46149 | C5: =IF(B5="","",TEXT(B5,"MMM-YYYY")) | D5: Land Development | E5: Labour | F5: Daily Labour-Mitti Bharai | G5: Site cleaning by Chanarveer (adhoc labour) | H5: Sonbhai-Coordinator | I5: 1 | J5: Lumpsum | K5: 1500 | L5: =IF(OR(I5="",K5=""),"",I5*K5) | N5: =M6*L6 | O5: =IF(L5="","",IF(M5="",L5,L5*(1-M5))) | P5: Self-GPay | Q5: GPay
A6: 3 | B6: 46153 | C6: =IF(B6="","",TEXT(B6,"MMM-YYYY")) | D6: Foundation | E6: Building Materials | F6: Cement | G6: Bill 63 - Ultratech Super 40 bags | H6: Pappu Hardware | I6: 40 | J6: Bags | K6: 360 | L6: =IF(OR(I6="",K6=""),"",I6*K6) | N6: =M7*L7 | O6: =IF(L6="","",IF(M6="",L6,L6*(1-M6))) | P6: Self-GPay | Q6: GPay
A7: 4 | B7: 46153 | C7: =IF(B7="","",TEXT(B7,"MMM-YYYY")) | D7: Foundation | E7: Steel / Iron | F7: Tiscon 12mm | G7: Bill 63 - Tiscon 12mm 100pcs | H7: Pappu Hardware | I7: 100 | J7: Pcs | K7: 908 | L7: =IF(OR(I7="",K7=""),"",I7*K7) | M7: 0.04 | N7: =M8*L8 | O7: =IF(L7="","",IF(M7="",L7,L7*(1-M7))) | P7: Self-GPay | Q7: GPay
A8: 5 | B8: 46153 | C8: =IF(B8="","",TEXT(B8,"MMM-YYYY")) | D8: Foundation | E8: Steel / Iron | F8: Tiscon 10mm | G8: Bill 63 - Tiscon 10mm 100pcs | H8: Pappu Hardware | I8: 100 | J8: Pcs | K8: 642 | L8: =IF(OR(I8="",K8=""),"",I8*K8) | M8: 0.04 | N8: =M9*L9 | O8: =IF(L8="","",IF(M8="",L8,L8*(1-M8))) | P8: Self-GPay | Q8: GPay
A9: 6 | B9: 46153 | C9: =IF(B9="","",TEXT(B9,"MMM-YYYY")) | D9: Foundation | E9: Steel / Iron | F9: Tiscon 6mm | G9: Bill 63 - Tiscon 6mm 50pcs | H9: Pappu Hardware | I9: 50 | J9: Pcs | K9: 246 | L9: =IF(OR(I9="",K9=""),"",I9*K9) | N9: =M10*L10 | O9: =IF(L9="","",IF(M9="",L9,L9*(1-M9))) | P9: Self-GPay | Q9: GPay
A10: 7 | B10: 46153 | C10: =IF(B10="","",TEXT(B10,"MMM-YYYY")) | D10: Foundation | E10: Building Materials | F10: Binding Wire | G10: Bill 63 - Binding Wire 20kg | H10: Pappu Hardware | I10: 20 | J10: Kg | K10: 120 | L10: =IF(OR(I10="",K10=""),"",I10*K10) | N10: =M11*L11 | O10: =IF(L10="","",IF(M10="",L10,L10*(1-M10))) | P10: Self-GPay | Q10: GPay
A11: 8 | B11: 46153 | C11: =IF(B11="","",TEXT(B11,"MMM-YYYY")) | D11: Foundation | E11: Building Materials | F11: Dr Fixit | G11: Bill 63 - Dr Fixit 10L x 2pcs | H11: Pappu Hardware | I11: 2 | J11: Litres | K11: 1400 | L11: =IF(OR(I11="",K11=""),"",I11*K11) | N11: =M12*L12 | O11: =IF(L11="","",IF(M11="",L11,L11*(1-M11))) | P11: Self-GPay | Q11: GPay
A12: 9 | B12: 46153 | C12: =IF(B12="","",TEXT(B12,"MMM-YYYY")) | D12: Foundation | E12: Transport · Food · Misc | F12: Truck/Tempo Freight | G12: Bill 63 - Transport from Pappu Hardware | H12: Pappu Hardware | I12: 1 | J12: Trips | K12: 250 | L12: =IF(OR(I12="",K12=""),"",I12*K12) | N12: =M13*L13 | O12: =IF(L12="","",IF(M12="",L12,L12*(1-M12))) | P12: Self-GPay | Q12: GPay
A13: 10 | B13: 46153 | C13: =IF(B13="","",TEXT(B13,"MMM-YYYY")) | D13: Foundation | E13: Labour | F13: Skilled Labour | G13: Bill 63 - Loading labour | H13: Pappu Hardware | I13: 1 | J13: Lumpsum | K13: 450 | L13: =IF(OR(I13="",K13=""),"",I13*K13) | N13: =M14*L14 | O13: =IF(L13="","",IF(M13="",L13,L13*(1-M13))) | P13: Self-GPay | Q13: GPay
A14: 11 | B14: 46153 | C14: =IF(B14="","",TEXT(B14,"MMM-YYYY")) | D14: Foundation | E14: Building Materials | F14: Nails | G14: Bill 63 - Kanti (Nails) 2"x1" 1 bag | H14: Pappu Hardware | I14: 1 | J14: Kg/Bags | K14: 2000 | L14: =IF(OR(I14="",K14=""),"",I14*K14) | N14: =M15*L15 | O14: =IF(L14="","",IF(M14="",L14,L14*(1-M14))) | P14: Self-GPay | Q14: GPay
A15: 12 | B15: 46153 | C15: =IF(B15="","",TEXT(B15,"MMM-YYYY")) | D15: Foundation | E15: Building Materials | F15: Nails | G15: Bill 63 - Additional discount from Pappu Hardware | H15: Pappu Hardware | I15: 1 | J15: Lumpsum | K15: -400 | L15: =IF(OR(I15="",K15=""),"",I15*K15) | N15: =M16*L16 | O15: =IF(L15="","",IF(M15="",L15,L15*(1-M15))) | P15: Self-GPay | Q15: GPay
A16: 13 | B16: 46154 | C16: =IF(B16="","",TEXT(B16,"MMM-YYYY")) | D16: Land Development | E16: Land Development | F16: JCB Work | G16: JCB work 17.5 hrs @ ₹1,000/hr | H16: Mukesh Yadav | I16: 17.5 | J16: Hrs | K16: 1000 | L16: =IF(OR(I16="",K16=""),"",I16*K16) | N16: =M17*L17 | O16: =IF(L16="","",IF(M16="",L16,L16*(1-M16))) | P16: Papa | Q16: GPay
A17: 14 | B17: 46146 | C17: =IF(B17="","",TEXT(B17,"MMM-YYYY")) | D17: Foundation | E17: Building Materials | F17: Sand | G17: Sand 1st truck (920 CFT) | H17: Sand Truck Wala | I17: 920 | J17: CFT | K17: 59.782609 | L17: =IF(OR(I17="",K17=""),"",I17*K17) | N17: =M18*L18 | O17: =IF(L17="","",IF(M17="",L17,L17*(1-M17))) | P17: Papa | Q17: GPay
A18: 15 | B18: 46154 | C18: =IF(B18="","",TEXT(B18,"MMM-YYYY")) | D18: Foundation | E18: Building Materials | F18: Sand | G18: Sand 2nd truck (918 CFT) | H18: Sand Truck Wala | I18: 918 | J18: CFT | K18: 59.912854 | L18: =IF(OR(I18="",K18=""),"",I18*K18) | N18: =M19*L19 | O18: =IF(L18="","",IF(M18="",L18,L18*(1-M18))) | P18: Papa | Q18: GPay
A19: 16 | B19: 46156 | C19: =IF(B19="","",TEXT(B19,"MMM-YYYY")) | D19: Foundation | E19: Building Materials | F19: Bricks | G19: Bricks - tractor 1 delivery (1500 pcs) | H19: Brick Company | I19: 1500 | J19: Nos | K19: 8.5 | L19: =IF(OR(I19="",K19=""),"",I19*K19) | O19: =IF(L19="","",IF(M19="",L19,L19*(1-M19))) | P19: Self-GPay | Q19: GPay
A20: 17 | B20: 46157 | C20: =IF(B20="","",TEXT(B20,"MMM-YYYY")) | D20: Foundation | E20: Building Materials | F20: Concrete/Gitti | G20: Crushed stone / Gitti - 27.5 Ton (600 CFT) | H20: Concrete Supplier | I20: 27.5 | J20: Ton | K20: 2400 | L20: =IF(OR(I20="",K20=""),"",I20*K20) | O20: =IF(L20="","",IF(M20="",L20,L20*(1-M20))) | P20: Papa | Q20: GPay
A21: 19 | B21: 46158 | C21: =IF(B21="","",TEXT(B21,"MMM-YYYY")) | D21: Foundation | E21: Professional Fees | F21: Engineering | G21: Engineer advance to Econ Builder (construction supervision) | H21: Econ Builder | I21: 1 | J21: Lumpsum | K21: 50000 | L21: =IF(OR(I21="",K21=""),"",I21*K21) | O21: =IF(L21="","",IF(M21="",L21,L21*(1-M21))) | P21: Self-GPay | Q21: GPay
A22: 20 | B22: 46157 | C22: =IF(B22="","",TEXT(B22,"MMM-YYYY")) | D22: Foundation | E22: Building Materials | F22: Bricks | G22: Bricks - tractor 2 delivery (1500 pcs) | H22: Brick Company | I22: 1500 | J22: Nos | K22: 8.5 | L22: =IF(OR(I22="",K22=""),"",I22*K22) | O22: =IF(L22="","",IF(M22="",L22,L22*(1-M22))) | P22: Self-GPay | Q22: GPay
A23: 21 | B23: 46157 | C23: =IF(B23="","",TEXT(B23,"MMM-YYYY")) | D23: Foundation | E23: Building Materials | F23: Bricks | G23: Bricks - tractor 3 delivery (1500 pcs) | H23: Brick Company | I23: 1500 | J23: Nos | K23: 8.5 | L23: =IF(OR(I23="",K23=""),"",I23*K23) | O23: =IF(L23="","",IF(M23="",L23,L23*(1-M23))) | P23: Self-GPay | Q23: GPay
A24: 22 | B24: 46157 | C24: =IF(B24="","",TEXT(B24,"MMM-YYYY")) | D24: Foundation | E24: Building Materials | F24: Bricks | G24: Bricks - tractor 4 delivery (1500 pcs) | H24: Brick Company | I24: 1500 | J24: Nos | K24: 8.5 | L24: =IF(OR(I24="",K24=""),"",I24*K24) | O24: =IF(L24="","",IF(M24="",L24,L24*(1-M24))) | P24: Self-GPay | Q24: GPay
A25: 23 | B25: 46157 | C25: =IF(B25="","",TEXT(B25,"MMM-YYYY")) | D25: Foundation | E25: Building Materials | F25: Bricks | G25: Bricks - tractor 5 delivery (1500 pcs) | H25: Brick Company | I25: 1500 | J25: Nos | K25: 8.5 | L25: =IF(OR(I25="",K25=""),"",I25*K25) | O25: =IF(L25="","",IF(M25="",L25,L25*(1-M25))) | P25: Self-GPay | Q25: GPay
A26: 24 | B26: 46158 | C26: =IF(B26="","",TEXT(B26,"MMM-YYYY")) | D26: Foundation | E26: Transport · Food · Misc | F26: Kala Panni/Tar | G26: Polythene / Panni | H26: Local Purchase | I26: 1 | J26: Lumpsum | K26: 600 | L26: =IF(OR(I26="",K26=""),"",I26*K26) | O26: =IF(L26="","",IF(M26="",L26,L26*(1-M26))) | P26: Papa | Q26: GPay
A27: 25 | B27: 46158 | C27: =IF(B27="","",TEXT(B27,"MMM-YYYY")) | D27: Foundation | E27: Transport · Food · Misc | F27: Tools/Equipment | G27: Construction equipment - Tegadi & Kudal | H27: Local Purchase | I27: 1 | J27: Lumpsum | K27: 1175 | L27: =IF(OR(I27="",K27=""),"",I27*K27) | O27: =IF(L27="","",IF(M27="",L27,L27*(1-M27))) | P27: Papa | Q27: GPay
A28: 26 | B28: 46158 | C28: =IF(B28="","",TEXT(B28,"MMM-YYYY")) | D28: Foundation | E28: Transport · Food · Misc | F28: Food/Ration | G28: Food ration for labour | H28: Local Purchase | I28: 1 | J28: Lumpsum | K28: 3285 | L28: =IF(OR(I28="",K28=""),"",I28*K28) | O28: =IF(L28="","",IF(M28="",L28,L28*(1-M28))) | P28: Papa | Q28: GPay
A29: 27 | B29: 46161 | C29: =IF(B29="","",TEXT(B29,"MMM-YYYY")) | D29: Foundation | E29: Building Materials | F29: Binding Wire | G29: Soft wire | H29: Pappu Hardware | I29: 1 | J29: Lumpsum | K29: 1300 | L29: =IF(OR(I29="",K29=""),"",I29*K29) | O29: =IF(L29="","",IF(M29="",L29,L29*(1-M29))) | P29: Self-GPay | Q29: GPay
A30: 28 | B30: 46161 | C30: =IF(B30="","",TEXT(B30,"MMM-YYYY")) | D30: Foundation | E30: Building Materials | F30: Cover Block | G30: Cover blocks - 6 packets | H30: Pappu Hardware | I30: 6 | J30: Nos | K30: 350 | L30: =IF(OR(I30="",K30=""),"",I30*K30) | O30: =IF(L30="","",IF(M30="",L30,L30*(1-M30))) | P30: Self-GPay | Q30: GPay
... A45: 43 | B45: 46166 | C45: =IF(B45="","",TEXT(B45,"MMM-YYYY")) | D45: Plinth | E45: Building Materials | F45: Bricks | G45: Bricks - tractor 9 delivery (1500 pcs) | H45: Brick Company | I45: 1500 | J45: Nos | K45: 8.5 | L45: =IF(OR(I45="",K45=""),"",I45*K45) | O45: =IF(L45="","",IF(M45="",L45,L45*(1-M45))) | P45: Self-GPay | Q45: GPay
A46: 45 | B46: 46167 | C46: =IF(B46="","",TEXT(B46,"MMM-YYYY")) | D46: Plinth | E46: Building Materials | F46: Bricks | G46: Bricks - tractor 10 delivery (1500 pcs) | H46: Brick Company | I46: 1500 | J46: Nos | K46: 8.5 | L46: =IF(OR(I46="",K46=""),"",I46*K46) | N46: =IF(L49="","",IF(M49="",0,L49*M49)) | O46: =IF(L46="","",IF(M46="",L46,L46*(1-M46))) | P46: Self-GPay | Q46: GPay
A47: 46 | B47: 46168 | C47: =IF(B47="","",TEXT(B47,"MMM-YYYY")) | D47: Plinth | E47: Building Materials | F47: Bricks | G47: Bricks - tractor 11 delivery (1500 pcs) | H47: Brick Company | I47: 1500 | J47: Nos | K47: 8.5 | L47: =IF(OR(I47="",K47=""),"",I47*K47) | N47: =IF(L50="","",IF(M50="",0,L50*M50)) | O47: =IF(L47="","",IF(M47="",L47,L47*(1-M47))) | P47: Self-GPay | Q47: GPay
A48: 47 | B48: 46168 | C48: =IF(B48="","",TEXT(B48,"MMM-YYYY")) | D48: Plinth | E48: Building Materials | F48: Bricks | G48: Bricks - tractor 12 delivery (1500 pcs) | H48: Brick Company | I48: 1500 | J48: Nos | K48: 8.5 | L48: =IF(OR(I48="",K48=""),"",I48*K48) | N48: =IF(L51="","",IF(M51="",0,L51*M51)) | O48: =IF(L48="","",IF(M48="",L48,L48*(1-M48))) | P48: Self-GPay | Q48: GPay
A49: 48 | B49: 46168 | C49: =IF(B49="","",TEXT(B49,"MMM-YYYY")) | D49: Plinth | E49: Land Development | F49: Mitti Filling | G49: Mitti filling - 22 trailers @ ₹600 each | H49: Mukesh Yadav | I49: 22 | J49: Nos | K49: 600 | L49: =IF(OR(I49="",K49=""),"",I49*K49) | N49: =IF(L52="","",IF(M52="",0,L52*M52)) | O49: =IF(L49="","",IF(M49="",L49,L49*(1-M49))) | P49: Papa | Q49: GPay
A50: 49 | B50: 46174 | C50: =IF(B50="","",TEXT(B50,"MMM-YYYY")) | D50: Plinth | E50: Steel / Iron | F50: Tiscon 12mm | G50: Tiscon 12mm TMT - 100 PC @ ₹908 (Bill 2) | H50: Pappu Hardware | I50: 100 | J50: Pcs | K50: 908 | L50: =IF(OR(I50="",K50=""),"",I50*K50) | M50: 0.04 | N50: =IF(L53="","",IF(M53="",0,L53*M53)) | O50: =IF(L50="","",IF(M50="",L50,L50*(1-M50))) | P50: Self-Bank Transfer | Q50: Bank Transfer
A51: 50 | B51: 46174 | C51: =IF(B51="","",TEXT(B51,"MMM-YYYY")) | D51: Plinth | E51: Steel / Iron | F51: Tiscon 10mm | G51: Tiscon 10mm TMT - 100 PC @ ₹642 (Bill 2) | H51: Pappu Hardware | I51: 100 | J51: Pcs | K51: 642 | L51: =IF(OR(I51="",K51=""),"",I51*K51) | M51: 0.04 | N51: =IF(L54="","",IF(M54="",0,L54*M54)) | O51: =IF(L51="","",IF(M51="",L51,L51*(1-M51))) | P51: Self-Bank Transfer | Q51: Bank Transfer
A52: 51 | B52: 46174 | C52: =IF(B52="","",TEXT(B52,"MMM-YYYY")) | D52: Plinth | E52: Steel / Iron | F52: Tiscon 8mm | G52: Tiscon 8mm TMT - 50 PC @ ₹420 (NEW) | H52: Pappu Hardware | I52: 50 | J52: Pcs | K52: 420 | L52: =IF(OR(I52="",K52=""),"",I52*K52) | M52: 0.04 | N52: =IF(L55="","",IF(M55="",0,L55*M55)) | O52: =IF(L52="","",IF(M52="",L52,L52*(1-M52))) | P52: Self-Bank Transfer | Q52: Bank Transfer
A53: 52 | B53: 46174 | C53: =IF(B53="","",TEXT(B53,"MMM-YYYY")) | D53: Plinth | E53: Steel / Iron | F53: Tiscon 6mm | G53: Tiscon 6mm TMT - 50 PC @ ₹246 (Bill 2) | H53: Pappu Hardware | I53: 50 | J53: Pcs | K53: 246 | L53: =IF(OR(I53="",K53=""),"",I53*K53) | N53: =IF(L56="","",IF(M56="",0,L56*M56)) | O53: =IF(L53="","",IF(M53="",L53,L53*(1-M53))) | P53: Self-Bank Transfer | Q53: Bank Transfer
A54: 53 | B54: 46174 | C54: =IF(B54="","",TEXT(B54,"MMM-YYYY")) | D54: Plinth | E54: Building Materials | F54: Cement | G54: Cement Ultratech Super - 50 bags (Bill 2) | H54: Pappu Hardware | I54: 50 | J54: Bags | K54: 360 | L54: =IF(OR(I54="",K54=""),"",I54*K54) | N54: =IF(L57="","",IF(M57="",0,L57*M57)) | O54: =IF(L54="","",IF(M54="",L54,L54*(1-M54))) | P54: Self-Bank Transfer | Q54: Bank Transfer
A55: 54 | B55: 46174 | C55: =IF(B55="","",TEXT(B55,"MMM-YYYY")) | D55: Plinth | E55: Building Materials | F55: Dr Fixit | G55: Dr Fixit 20 litre - 1 pack | H55: Pappu Hardware | I55: 20 | J55: L | K55: 130 | L55: =IF(OR(I55="",K55=""),"",I55*K55) | N55: =IF(L58="","",IF(M58="",0,L58*M58)) | O55: =IF(L55="","",IF(M55="",L55,L55*(1-M55))) | P55: Self-Bank Transfer | Q55: Bank Transfer
...

Sheet Bill Entry
A1: VENDOR BILL / INVOICE — LINE ENTRY (RETIRED — not maintained since May; use All Transactions)
A2: When a paper bill arrives, enter each line item here. Same Bill No groups items of one bill.
A4: Bill No | B4: Bill Date | C4: Vendor | D4: Category | E4: Sub-Category | F4: Item Description | G4: HSN/SAC | H4: Qty | I4: Unit | J4: Rate ₹ | K4: Line Amt ₹ | L4: Discount/Adj ₹ | M4: Transport ₹ | N4: Labour Charge ₹ | O4: Bill Total ₹
A5: 63 | B5: 46153 | C5: Pappu Hardware | D5: Building Materials | E5: Cement-Ultratech Super | F5: Ultratech Super Cement | H5: 40 | I5: Bags | J5: 360 | K5: =IF(OR(H5="",J5=""),"",H5*J5) | O5: =IF(K5="","",K5-IF(L5="",0,L5)+IF(M5="",0,M5)+IF(N5="",0,N5))
A6: 63 | B6: 46153 | C6: Pappu Hardware | D6: Steel/Iron | E6: Tiscon 12mm | F6: Tiscon 12mm | H6: 100 | I6: Pcs | J6: 908 | K6: =IF(OR(H6="",J6=""),"",H6*J6) | O6: =IF(K6="","",K6-IF(L6="",0,L6)+IF(M6="",0,M6)+IF(N6="",0,N6))
A7: 63 | B7: 46153 | C7: Pappu Hardware | D7: Steel/Iron | E7: Tiscon 10mm | F7: Tiscon 10mm | H7: 100 | I7: Pcs | J7: 642 | K7: =IF(OR(H7="",J7=""),"",H7*J7) | O7: =IF(K7="","",K7-IF(L7="",0,L7)+IF(M7="",0,M7)+IF(N7="",0,N7))
A8: 63 | B8: 46153 | C8: Pappu Hardware | D8: Steel/Iron | E8: Tiscon 6mm | F8: Tiscon 6mm | H8: 50 | I8: Pcs | J8: 246 | K8: =IF(OR(H8="",J8=""),"",H8*J8) | O8: =IF(K8="","",K8-IF(L8="",0,L8)+IF(M8="",0,M8)+IF(N8="",0,N8))
A9: 63 | B9: 46153 | C9: Pappu Hardware | D9: Building Materials | E9: Binding Wire | F9: Binding Wire 20kg | H9: 20 | I9: Kg | J9: 600 | K9: =IF(OR(H9="",J9=""),"",H9*J9) | O9: =IF(K9="","",K9-IF(L9="",0,L9)+IF(M9="",0,M9)+IF(N9="",0,N9))
A10: 63 | B10: 46153 | C10: Pappu Hardware | D10: Building Materials | E10: Dr Fixit | F10: Dr Fixit 10L x 2pcs | H10: 2 | I10: Litres | J10: 1400 | K10: =IF(OR(H10="",J10=""),"",H10*J10) | O10: =IF(K10="","",K10-IF(L10="",0,L10)+IF(M10="",0,M10)+IF(N10="",0,N10))
A11: 63 | B11: 46153 | C11: Pappu Hardware | D11: Transport | E11: Truck/Tempo Freight | F11: Transport | H11: 1 | I11: Trips | J11: 250 | K11: =IF(OR(H11="",J11=""),"",H11*J11) | O11: =IF(K11="","",K11-IF(L11="",0,L11)+IF(M11="",0,M11)+IF(N11="",0,N11))
A12: 63 | B12: 46153 | C12: Pappu Hardware | D12: Labour | E12: Skilled Labour | F12: Loading labour | H12: 1 | I12: Lumpsum | J12: 450 | K12: =IF(OR(H12="",J12=""),"",H12*J12) | O12: =IF(K12="","",K12-IF(L12="",0,L12)+IF(M12="",0,M12)+IF(N12="",0,N12))
A13: 63 | B13: 46153 | C13: Pappu Hardware | D13: Building Materials | E13: Nails | F13: Kanti (Nails) 2"x1" - 1 bag | H13: 1 | I13: Kg/Bags | J13: 2000 | K13: =IF(OR(H13="",J13=""),"",H13*J13) | O13: =IF(K13="","",K13-IF(L13="",0,L13)+IF(M13="",0,M13)+IF(N13="",0,N13))
K14: =IF(OR(H14="",J14=""),"",H14*J14) | O14: =IF(K14="","",K14-IF(L14="",0,L14)+IF(M14="",0,M14)+IF(N14="",0,N14))
K15: =IF(OR(H15="",J15=""),"",H15*J15) | O15: =IF(K15="","",K15-IF(L15="",0,L15)+IF(M15="",0,M15)+IF(N15="",0,N15))
K16: =IF(OR(H16="",J16=""),"",H16*J16) | O16: =IF(K16="","",K16-IF(L16="",0,L16)+IF(M16="",0,M16)+IF(N16="",0,N16))
K17: =IF(OR(H17="",J17=""),"",H17*J17) | O17: =IF(K17="","",K17-IF(L17="",0,L17)+IF(M17="",0,M17)+IF(N17="",0,N17))
K18: =IF(OR(H18="",J18=""),"",H18*J18) | O18: =IF(K18="","",K18-IF(L18="",0,L18)+IF(M18="",0,M18)+IF(N18="",0,N18))
K19: =IF(OR(H19="",J19=""),"",H19*J19) | O19: =IF(K19="","",K19-IF(L19="",0,L19)+IF(M19="",0,M19)+IF(N19="",0,N19))
K20: =IF(OR(H20="",J20=""),"",H20*J20) | O20: =IF(K20="","",K20-IF(L20="",0,L20)+IF(M20="",0,M20)+IF(N20="",0,N20))
K21: =IF(OR(H21="",J21=""),"",H21*J21) | O21: =IF(K21="","",K21-IF(L21="",0,L21)+IF(M21="",0,M21)+IF(N21="",0,N21))
K22: =IF(OR(H22="",J22=""),"",H22*J22) | O22: =IF(K22="","",K22-IF(L22="",0,L22)+IF(M22="",0,M22)+IF(N22="",0,N22))
K23: =IF(OR(H23="",J23=""),"",H23*J23) | O23: =IF(K23="","",K23-IF(L23="",0,L23)+IF(M23="",0,M23)+IF(N23="",0,N23))
K24: =IF(OR(H24="",J24=""),"",H24*J24) | O24: =IF(K24="","",K24-IF(L24="",0,L24)+IF(M24="",0,M24)+IF(N24="",0,N24))
K25: =IF(OR(H25="",J25=""),"",H25*J25) | O25: =IF(K25="","",K25-IF(L25="",0,L25)+IF(M25="",0,M25)+IF(N25="",0,N25))
... K504: =IF(OR(H504="",J504=""),"",H504*J504) | O504: =IF(K504="","",K504-IF(L504="",0,L504)+IF(M504="",0,M504)+IF(N504="",0,N504))

Sheet Payment Tracker
A1: PAYMENT TRACKER — Full Audit Trail
A2: Track every payment: who paid, to whom, how, reference number.
A4: Sr No | B4: Date | C4: Paid By | D4: Paid To (Vendor) | E4: Category | F4: Purpose/Description | G4: Amount ₹ | H4: Payment Mode | I4: UPI/Txn Ref | J4: Phone No | K4: Receipt Y/N | L4: Running Total ₹ | M4: Remarks
A5: 1 | B5: 46146 | C5: Papa | D5: Sand Truck Wala | F5: Sand Truck 1 (920 CFT) | G5: 55000 | H5: GPay | K5: Y | L5: =G5
A6: 3 | B6: 46149 | C6: Self-GPay | D6: Sonbhai-Coordinator | F6: Site cleaning | G6: 1500 | H6: GPay | K6: Y | L6: =IF(G6="","",IF(L5="",G6,L5+G6))
A7: 4 | B7: 46153 | C7: Self-GPay | D7: Pappu Hardware | F7: Bill 63 — part 1 | G7: 90000 | H7: GPay | K7: Y | L7: =IF(G7="","",IF(L6="",G7,L6+G7))
A8: 5 | B8: 46154 | C8: Papa | D8: Mukesh Yadav | F8: JCB advance | G8: 5000 | H8: GPay | K8: Y | L8: =IF(G8="","",IF(L7="",G8,L7+G8))
A9: 6 | B9: 46154 | C9: Papa | D9: Sand Truck Wala | F9: Sand Truck 2 (918 CFT) | G9: 55000 | H9: GPay | K9: Y | L9: =IF(G9="","",IF(L8="",G9,L8+G9))
A10: 7 | B10: 46155 | C10: Self-GPay | D10: Pappu Hardware | F10: Bill 63 — part 2 final | G10: 93000 | H10: GPay | K10: Y | L10: =IF(G10="","",IF(L9="",G10,L9+G10))
A11: 8 | B11: 46156 | C11: Self-GPay | D11: Brick Company | F11: Brick advance — Avinash share | G11: 200000 | H11: GPay | K11: Y | L11: =IF(G11="","",IF(L10="",G11,L10+G11))
A12: 9 | B12: 46156 | C12: Chota Bhai | D12: Brick Company | F12: Brick advance — Chota Bhai share | G12: 169000 | H12: GPay | K12: Y | L12: =IF(G12="","",IF(L11="",G12,L11+G12))
A13: 10 | B13: 46157 | C13: Papa | D13: Concrete Supplier | F13: Gitti 27.5T @ ₹2,400 | G13: 66000 | H13: GPay | K13: Y | L13: =IF(G13="","",IF(L12="",G13,L12+G13))
A14: 12 | B14: 46158 | C14: Self-GPay | D14: Econ Builder | F14: Supervision advance | G14: 50000 | H14: GPay | K14: Y | L14: =IF(G14="","",IF(L13="",G14,L13+G14))
A15: 13 | B15: 46158 | C15: Papa | D15: Local Purchase | F15: Panni + tools + food | G15: 5060 | H15: GPay | K15: Y | L15: =IF(G15="","",IF(L14="",G15,L14+G15))
A16: 14 | B16: 46161 | C16: Self-GPay | D16: Pappu Hardware | F16: Soft wire + cover blocks | G16: 3500 | H16: GPay | K16: Y | L16: =IF(G16="","",IF(L15="",G16,L15+G16))
A17: 15 | B17: 46163 | C17: Self-GPay | D17: Pappu Hardware | F17: Cement 60B + metal sheet | G17: 24800 | H17: GPay | K17: Y | L17: =IF(G17="","",IF(L16="",G17,L16+G17))
... A26: 25 | B26: 46183 | C26: Self-Bank Transfer | D26: Mukesh Yadav | F26: Final settlement — JCB + Mitti + Sand + Gitti movement | G26: 58200 | H26: Bank | K26: Y | L26: =IF(G26="","",IF(L25="",G26,L25+G26))
A27: 26 | B27: 46194 | C27: Self-GPay | D27: Pappu Hardware | E27: Building Materials | F27: Cement 50B + transport + labour | G27: 18500 | H27: GPay | K27: Y | L27: =IF(G27="","",IF(L26="",G27,L26+G27))
A28: 27 | B28: 46194 | C28: Self-GPay | D28: Pappu Hardware | E28: Building Materials | F28: Soft wire 10 Kg — Bill 4 settlement | G28: 1300 | H28: GPay | K28: Y | L28: =IF(G28="","",IF(L27="",G28,L27+G28))
A29: 28 | B29: 46195 | C29: Papa | D29: Daily Labour | E29: Labour | F29: Mitti bharai labour payment | G29: 2000 | H29: GPay | K29: Y | L29: =IF(G29="","",IF(L28="",G29,L28+G29))
A30: 29 | B30: 46196 | C30: Papa | D30: Daily Labour | E30: Labour | F30: Full labour settlement — mitti bharai + kitchen | G30: 16300 | H30: GPay | K30: Y | L30: =IF(G30="","",IF(L29="",G30,L29+G30))
A31: 30 | B31: 46208 | C31: Self | D31: Mukesh Yadav | E31: Land Development | F31: Mitti + JCB balance payment | G31: 30000 | H31: GPay | K31: Y | L31: =IF(G31="","",IF(L30="",G31,L30+G31))
A32: 32 | B32: 46208 | C32: Self | D32: Econ Builder | E32: Professional Fees | F32: Engineer supervision fee — Jul payment | G32: 75000 | H32: GPay | K32: Y | L32: =IF(G32="","",IF(L31="",G32,L31+G32))
A33: 33 | B33: 46208 | C33: Self | D33: Sand Truck Wala | E33: Building Materials | F33: Sand Truck 3 — 944 CFT | G33: 46500 | H33: GPay | K33: Y | L33: =IF(G33="","",IF(L32="",G33,L32+G33))
A34: 34 | B34: 46208 | C34: Papa | D34: Sand Truck Wala | E34: Building Materials | F34: Sand Truck 3 — 944 CFT | G34: 10000 | H34: GPay | K34: Y | L34: =IF(G34="","",IF(L33="",G34,L33+G34))
A35: 35 | B35: 46208 | C35: Self | D35: Sand Truck Wala | E35: Building Materials | F35: Sand Truck 4 — 936 CFT | G35: 56000 | H35: GPay | K35: Y | L35: =IF(G35="","",IF(L34="",G35,L34+G35))
A36: 36 | B36: 46208 | C36: Self | D36: Pappu Hardware | E36: Building Materials + Steel + Labour | F36: Cement 60B + 6mm 50pcs + Gitti + DrFixit + Labour | G36: 41650 | H36: GPay | K36: Y | L36: =IF(G36="","",IF(L35="",G36,L35+G36))
A37: 38 | B37: 46220 | C37: Papa | D37: Local Purchase | E37: Building Materials | F37: Iron wire 2kg + delivery | G37: 1300 | H37: GPay | K37: Y | L37: =IF(G37="","",IF(L36="",G37,L36+G37))
A38: 40 | B38: 46221 | C38: Self | D38: Mukesh Yadav | E38: Land Development + Labour | F38: JCB + Mitti + Sand movement balance payment | G38: 40000 | H38: Cash | K38: Y | L38: =IF(G38="","",IF(L37="",G38,L37+G38))
... A110: 116 | B110: 46308 | C110: Self | D110: Pappu Hardware | E110: Steel / Iron + Cement + Building Materials | F110: Full payment — 13-Oct bill (₹1,42,843) | G110: 142843 | H110: Cash | K110: Y | L110: =IF(G110="","",IF(L109="",G110,L109+G110))
A111: 117 | L111: =IF(G111="","",IF(L110="",G111,L110+G111))
A112: 118 | L112: =IF(G112="","",IF(L111="",G112,L111+G112))
A113: 119 | L113: =IF(G113="","",IF(L112="",G113,L112+G113))
A114: 120 | L114: =IF(G114="","",IF(L113="",G114,L113+G114))
A115: 121 | L115: =IF(G115="","",IF(L114="",G115,L114+G115))
A116: 122 | L116: =IF(G116="","",IF(L115="",G116,L115+G116))
A117: 123 | L117: =IF(G117="","",IF(L116="",G117,L116+G117))
A118: 124 | L118: =IF(G118="","",IF(L117="",G118,L117+G118))
A119: 125 | L119: =IF(G119="","",IF(L118="",G119,L118+G119))
A120: 126 | L120: =IF(G120="","",IF(L119="",G120,L119+G120))
...

Sheet Material Summary
A1: MATERIAL PURCHASE SUMMARY
A2: Auto-calculated from All Transactions using SUMIFS. No manual entry needed.
A4: Category | B4: Sub-Category | C4: Total Qty | D4: Unit | E4: Avg Rate ₹ | F4: Total Gross ₹ | G4: Total Discount ₹ | H4: Total Net ₹ | I4: % of Total
A5: Building Materials | B5: Bricks | C5: =SUMIFS('All Transactions'!I:I,'All Transactions'!E:E,A5,'All Transactions'!F:F,B5,'All Transactions'!J:J,"<>Lumpsum",'All Transactions'!J:J,"<>Service",'All Transactions'!J:J,"<>Lot",'All Transactions'!J:J,"<>Advance") | D5: pcs | E5: =IFERROR(IF(C5=0,"",F5/C5),"") | F5: =SUMIFS('All Transactions'!L:L,'All Transactions'!E:E,A5,'All Transactions'!F:F,B5) | G5: =F5-H5 | H5: =SUMIFS('All Transactions'!O:O,'All Transactions'!E:E,A5,'All Transactions'!F:F,B5) | I5: =IFERROR(H5/H$35,"")
A6: Steel / Iron | B6: Tiscon 10mm | C6: =SUMIFS('All Transactions'!I:I,'All Transactions'!E:E,A6,'All Transactions'!F:F,B6,'All Transactions'!J:J,"<>Lumpsum",'All Transactions'!J:J,"<>Service",'All Transactions'!J:J,"<>Lot",'All Transactions'!J:J,"<>Advance") | D6: pcs | E6: =IFERROR(IF(C6=0,"",F6/C6),"") | F6: =SUMIFS('All Transactions'!L:L,'All Transactions'!E:E,A6,'All Transactions'!F:F,B6) | G6: =F6-H6 | H6: =SUMIFS('All Transactions'!O:O,'All Transactions'!E:E,A6,'All Transactions'!F:F,B6) | I6: =IFERROR(H6/H$35,"")
A7: Building Materials | B7: Concrete/Gitti | C7: =SUMIFS('All Transactions'!I:I,'All Transactions'!E:E,A7,'All Transactions'!F:F,B7,'All Transactions'!J:J,"<>Lumpsum",'All Transactions'!J:J,"<>Service",'All Transactions'!J:J,"<>Lot",'All Transactions'!J:J,"<>Advance") | D7: mixed | E7: =IFERROR(IF(C7=0,"",F7/C7),"") | F7: =SUMIFS('All Transactions'!L:L,'All Transactions'!E:E,A7,'All Transactions'!F:F,B7) | G7: =F7-H7 | H7: =SUMIFS('All Transactions'!O:O,'All Transactions'!E:E,A7,'All Transactions'!F:F,B7) | I7: =IFERROR(H7/H$35,"")
A8: Building Materials | B8: Sand | C8: =SUMIFS('All Transactions'!I:I,'All Transactions'!E:E,A8,'All Transactions'!F:F,B8,'All Transactions'!J:J,"<>Lumpsum",'All Transactions'!J:J,"<>Service",'All Transactions'!J:J,"<>Lot",'All Transactions'!J:J,"<>Advance") | D8: mixed | E8: =IFERROR(IF(C8=0,"",F8/C8),"") | F8: =SUMIFS('All Transactions'!L:L,'All Transactions'!E:E,A8,'All Transactions'!F:F,B8) | G8: =F8-H8 | H8: =SUMIFS('All Transactions'!O:O,'All Transactions'!E:E,A8,'All Transactions'!F:F,B8) | I8: =IFERROR(H8/H$35,"")
A9: Building Materials | B9: Cement | C9: =SUMIFS('All Transactions'!I:I,'All Transactions'!E:E,A9,'All Transactions'!F:F,B9,'All Transactions'!J:J,"<>Lumpsum",'All Transactions'!J:J,"<>Service",'All Transactions'!J:J,"<>Lot",'All Transactions'!J:J,"<>Advance") | D9: bags | E9: =IFERROR(IF(C9=0,"",F9/C9),"") | F9: =SUMIFS('All Transactions'!L:L,'All Transactions'!E:E,A9,'All Transactions'!F:F,B9) | G9: =F9-H9 | H9: =SUMIFS('All Transactions'!O:O,'All Transactions'!E:E,A9,'All Transactions'!F:F,B9) | I9: =IFERROR(H9/H$35,"")
A10: Steel / Iron | B10: Tiscon 12mm | C10: =SUMIFS('All Transactions'!I:I,'All Transactions'!E:E,A10,'All Transactions'!F:F,B10,'All Transactions'!J:J,"<>Lumpsum",'All Transactions'!J:J,"<>Service",'All Transactions'!J:J,"<>Lot",'All Transactions'!J:J,"<>Advance") | D10: pcs | E10: =IFERROR(IF(C10=0,"",F10/C10),"") | F10: =SUMIFS('All Transactions'!L:L,'All Transactions'!E:E,A10,'All Transactions'!F:F,B10) | G10: =F10-H10 | H10: =SUMIFS('All Transactions'!O:O,'All Transactions'!E:E,A10,'All Transactions'!F:F,B10) | I10: =IFERROR(H10/H$35,"")
A11: Steel / Iron | B11: Tiscon 8mm | C11: =SUMIFS('All Transactions'!I:I,'All Transactions'!E:E,A11,'All Transactions'!F:F,B11,'All Transactions'!J:J,"<>Lumpsum",'All Transactions'!J:J,"<>Service",'All Transactions'!J:J,"<>Lot",'All Transactions'!J:J,"<>Advance") | D11: pcs | E11: =IFERROR(IF(C11=0,"",F11/C11),"") | F11: =SUMIFS('All Transactions'!L:L,'All Transactions'!E:E,A11,'All Transactions'!F:F,B11) | G11: =F11-H11 | H11: =SUMIFS('All Transactions'!O:O,'All Transactions'!E:E,A11,'All Transactions'!F:F,B11) | I11: =IFERROR(H11/H$35,"")
A12: Steel / Iron | B12: Tiscon 6mm | C12: =SUMIFS('All Transactions'!I:I,'All Transactions'!E:E,A12,'All Transactions'!F:F,B12,'All Transactions'!J:J,"<>Lumpsum",'All Transactions'!J:J,"<>Service",'All Transactions'!J:J,"<>Lot",'All Transactions'!J:J,"<>Advance") | D12: pcs | E12: =IFERROR(IF(C12=0,"",F12/C12),"") | F12: =SUMIFS('All Transactions'!L:L,'All Transactions'!E:E,A12,'All Transactions'!F:F,B12) | G12: =F12-H12 | H12: =SUMIFS('All Transactions'!O:O,'All Transactions'!E:E,A12,'All Transactions'!F:F,B12) | I12: =IFERROR(H12/H$35,"")
A13: Building Materials | B13: Wood | C13: =SUMIFS('All Transactions'!I:I,'All Transactions'!E:E,A13,'All Transactions'!F:F,B13,'All Transactions'!J:J,"<>Lumpsum",'All Transactions'!J:J,"<>Service",'All Transactions'!J:J,"<>Lot",'All Transactions'!J:J,"<>Advance") | D13: cft | E13: =IFERROR(IF(C13=0,"",F13/C13),"") | F13: =SUMIFS('All Transactions'!L:L,'All Transactions'!E:E,A13,'All Transactions'!F:F,B13) | G13: =F13-H13 | H13: =SUMIFS('All Transactions'!O:O,'All Transactions'!E:E,A13,'All Transactions'!F:F,B13) | I13: =IFERROR(H13/H$35,"")
A14: Electrical | B14: Electrical Items | C14: =SUMIFS('All Transactions'!I:I,'All Transactions'!E:E,A14,'All Transactions'!F:F,B14,'All Transactions'!J:J,"<>Lumpsum",'All Transactions'!J:J,"<>Service",'All Transactions'!J:J,"<>Lot",'All Transactions'!J:J,"<>Advance") | D14: — | E14: =IFERROR(IF(C14=0,"",F14/C14),"") | F14: =SUMIFS('All Transactions'!L:L,'All Transactions'!E:E,A14,'All Transactions'!F:F,B14) | G14: =F14-H14 | H14: =SUMIFS('All Transactions'!O:O,'All Transactions'!E:E,A14,'All Transactions'!F:F,B14) | I14: =IFERROR(H14/H$35,"")
A15: Building Materials | B15: Dr Fixit | C15: =SUMIFS('All Transactions'!I:I,'All Transactions'!E:E,A15,'All Transactions'!F:F,B15,'All Transactions'!J:J,"<>Lumpsum",'All Transactions'!J:J,"<>Service",'All Transactions'!J:J,"<>Lot",'All Transactions'!J:J,"<>Advance") | D15: litres | E15: =IFERROR(IF(C15=0,"",F15/C15),"") | F15: =SUMIFS('All Transactions'!L:L,'All Transactions'!E:E,A15,'All Transactions'!F:F,B15) | G15: =F15-H15 | H15: =SUMIFS('All Transactions'!O:O,'All Transactions'!E:E,A15,'All Transactions'!F:F,B15) | I15: =IFERROR(H15/H$35,"")
A16: Steel / Iron | B16: Tiscon 16mm | C16: =SUMIFS('All Transactions'!I:I,'All Transactions'!E:E,A16,'All Transactions'!F:F,B16,'All Transactions'!J:J,"<>Lumpsum",'All Transactions'!J:J,"<>Service",'All Transactions'!J:J,"<>Lot",'All Transactions'!J:J,"<>Advance") | D16: pcs | E16: =IFERROR(IF(C16=0,"",F16/C16),"") | F16: =SUMIFS('All Transactions'!L:L,'All Transactions'!E:E,A16,'All Transactions'!F:F,B16) | G16: =F16-H16 | H16: =SUMIFS('All Transactions'!O:O,'All Transactions'!E:E,A16,'All Transactions'!F:F,B16) | I16: =IFERROR(H16/H$35,"")
... A24: Building Materials | B24: Material Transport | C24: =SUMIFS('All Transactions'!I:I,'All Transactions'!E:E,A24,'All Transactions'!F:F,B24,'All Transactions'!J:J,"<>Lumpsum",'All Transactions'!J:J,"<>Service",'All Transactions'!J:J,"<>Lot",'All Transactions'!J:J,"<>Advance") | D24: trips | E24: =IFERROR(IF(C24=0,"",F24/C24),"") | F24: =SUMIFS('All Transactions'!L:L,'All Transactions'!E:E,A24,'All Transactions'!F:F,B24) | G24: =F24-H24 | H24: =SUMIFS('All Transactions'!O:O,'All Transactions'!E:E,A24,'All Transactions'!F:F,B24) | I24: =IFERROR(H24/H$35,"")
A35: TOTAL MATERIALS | F35: =SUM(F5:F34) | G35: =SUM(G5:G34) | H35: =SUM(H5:H34)

Sheet Labour Tracker
A1: ENGINEER & LABOUR PAYMENT TRACKER (RETIRED — not maintained since May; use Payment Tracker)
A2: All payments to Engineer, Sonbhai, daily labour. Track by shift and purpose.
A4: Sr No | B4: Date | C4: Shift/Period | D4: Paid To | E4: Purpose | F4: Amount ₹ | G4: Payment Mode | H4: Paid By | I4: Running Total ₹ | J4: Remarks
A5: 1 | B5: 46149 | C5: One-time | D5: Econ Builder | E5: Visit Charge | F5: 5000 | G5: GPay | H5: Papa | I5: =IF(F5="","",F5) | J5: Advance for new house construction
A6: 2 | B6: 46149 | C6: Daily | D6: Daily Labour | E6: Labour Wages | F6: 1500 | G6: GPay | H6: Self-GPay | I6: =IF(F6="","",IF(I5="",F6,I5+F6)) | J6: Chanarveer - site cleaning
A7: 3 | I7: =IF(F7="","",IF(I6="",F7,I6+F7))
A8: 4 | I8: =IF(F8="","",IF(I7="",F8,I7+F8))
A9: 5 | I9: =IF(F9="","",IF(I8="",F9,I8+F9))
A10: 6 | I10: =IF(F10="","",IF(I9="",F10,I9+F10))
A11: 7 | I11: =IF(F11="","",IF(I10="",F11,I10+F11))
A12: 8 | I12: =IF(F12="","",IF(I11="",F12,I11+F12))
A13: 9 | I13: =IF(F13="","",IF(I12="",F13,I12+F13))
A14: 10 | I14: =IF(F14="","",IF(I13="",F14,I13+F14))
A15: 11 | I15: =IF(F15="","",IF(I14="",F15,I14+F15))
A16: 12 | I16: =IF(F16="","",IF(I15="",F16,I15+F16))
A17: 13 | I17: =IF(F17="","",IF(I16="",F17,I16+F17))
A18: 14 | I18: =IF(F18="","",IF(I17="",F18,I17+F18))
... A504: 500 | I504: =IF(F504="","",IF(I503="",F504,I503+F504))

Sheet Monthly Summary
A1: MONTH-WISE EXPENSE SUMMARY
A2: Auto-calculated from All Transactions using SUMIFS by month and category.
A4: Month | B4: Building Materials ₹ | C4: Steel / Iron ₹ | D4: Electrical ₹ | E4: Labour ₹ | F4: Professional Fees ₹ | G4: Land Development ₹ | H4: Transport · Food · Misc ₹ | I4: TOTAL ₹
A5: May-2026 | B5: =SUMIFS('All Transactions'!O:O,'All Transactions'!C:C,$A5,'All Transactions'!E:E,"Building Materials") | C5: =SUMIFS('All Transactions'!O:O,'All Transactions'!C:C,$A5,'All Transactions'!E:E,"Steel / Iron") | D5: =SUMIFS('All Transactions'!O:O,'All Transactions'!C:C,$A5,'All Transactions'!E:E,"Electrical") | E5: =SUMIFS('All Transactions'!O:O,'All Transactions'!C:C,$A5,'All Transactions'!E:E,"Labour") | F5: =SUMIFS('All Transactions'!O:O,'All Transactions'!C:C,$A5,'All Transactions'!E:E,"Professional Fees") | G5: =SUMIFS('All Transactions'!O:O,'All Transactions'!C:C,$A5,'All Transactions'!E:E,"Land Development") | H5: =SUMIFS('All Transactions'!O:O,'All Transactions'!C:C,$A5,'All Transactions'!E:E,"Transport · Food · Misc") | I5: =SUM(B5:H5)
A6: Jun-2026 | B6: =SUMIFS('All Transactions'!O:O,'All Transactions'!C:C,$A6,'All Transactions'!E:E,"Building Materials") | C6: =SUMIFS('All Transactions'!O:O,'All Transactions'!C:C,$A6,'All Transactions'!E:E,"Steel / Iron") | D6: =SUMIFS('All Transactions'!O:O,'All Transactions'!C:C,$A6,'All Transactions'!E:E,"Electrical") | E6: =SUMIFS('All Transactions'!O:O,'All Transactions'!C:C,$A6,'All Transactions'!E:E,"Labour") | F6: =SUMIFS('All Transactions'!O:O,'All Transactions'!C:C,$A6,'All Transactions'!E:E,"Professional Fees") | G6: =SUMIFS('All Transactions'!O:O,'All Transactions'!C:C,$A6,'All Transactions'!E:E,"Land Development") | H6: =SUMIFS('All Transactions'!O:O,'All Transactions'!C:C,$A6,'All Transactions'!E:E,"Transport · Food · Misc") | I6: =SUM(B6:H6)
A7: Jul-2026 | B7: =SUMIFS('All Transactions'!O:O,'All Transactions'!C:C,$A7,'All Transactions'!E:E,"Building Materials") | C7: =SUMIFS('All Transactions'!O:O,'All Transactions'!C:C,$A7,'All Transactions'!E:E,"Steel / Iron") | D7: =SUMIFS('All Transactions'!O:O,'All Transactions'!C:C,$A7,'All Transactions'!E:E,"Electrical") | E7: =SUMIFS('All Transactions'!O:O,'All Transactions'!C:C,$A7,'All Transactions'!E:E,"Labour") | F7: =SUMIFS('All Transactions'!O:O,'All Transactions'!C:C,$A7,'All Transactions'!E:E,"Professional Fees") | G7: =SUMIFS('All Transactions'!O:O,'All Transactions'!C:C,$A7,'All Transactions'!E:E,"Land Development") | H7: =SUMIFS('All Transactions'!O:O,'All Transactions'!C:C,$A7,'All Transactions'!E:E,"Transport · Food · Misc") | I7: =SUM(B7:H7)
A8: Aug-2026 | B8: =SUMIFS('All Transactions'!O:O,'All Transactions'!C:C,$A8,'All Transactions'!E:E,"Building Materials") | C8: =SUMIFS('All Transactions'!O:O,'All Transactions'!C:C,$A8,'All Transactions'!E:E,"Steel / Iron") | D8: =SUMIFS('All Transactions'!O:O,'All Transactions'!C:C,$A8,'All Transactions'!E:E,"Electrical") | E8: =SUMIFS('All Transactions'!O:O,'All Transactions'!C:C,$A8,'All Transactions'!E:E,"Labour") | F8: =SUMIFS('All Transactions'!O:O,'All Transactions'!C:C,$A8,'All Transactions'!E:E,"Professional Fees") | G8: =SUMIFS('All Transactions'!O:O,'All Transactions'!C:C,$A8,'All Transactions'!E:E,"Land Development") | H8: =SUMIFS('All Transactions'!O:O,'All Transactions'!C:C,$A8,'All Transactions'!E:E,"Transport · Food · Misc") | I8: =SUM(B8:H8)
A9: Sep-2026 | B9: =SUMIFS('All Transactions'!O:O,'All Transactions'!C:C,$A9,'All Transactions'!E:E,"Building Materials") | C9: =SUMIFS('All Transactions'!O:O,'All Transactions'!C:C,$A9,'All Transactions'!E:E,"Steel / Iron") | D9: =SUMIFS('All Transactions'!O:O,'All Transactions'!C:C,$A9,'All Transactions'!E:E,"Electrical") | E9: =SUMIFS('All Transactions'!O:O,'All Transactions'!C:C,$A9,'All Transactions'!E:E,"Labour") | F9: =SUMIFS('All Transactions'!O:O,'All Transactions'!C:C,$A9,'All Transactions'!E:E,"Professional Fees") | G9: =SUMIFS('All Transactions'!O:O,'All Transactions'!C:C,$A9,'All Transactions'!E:E,"Land Development") | H9: =SUMIFS('All Transactions'!O:O,'All Transactions'!C:C,$A9,'All Transactions'!E:E,"Transport · Food · Misc") | I9: =SUM(B9:H9)
